Workbook

Sheet Demand Framework
A1: Demand Pressure - the framework
A2: Question this answers: 'Which queues need extra help right now?' Four live signals are turned into scores, weighted, and combined into a 0-100 pressure score and a band for every voice queue.
A3: Tabs: 'Calculation Trace' - pick a dashboard row and see how its score was worked out (formula | value | explanation). 'Calculator' - all queues and scenarios side by side. 'Assumptions & Open Items' - where every number came from and what is not yet settled. Mint = value set by configuration (edit to test). Purple = live data. Yellow = key result. Amber = not settled.
A5: 1. Design objectives - what a good demand score must do (from the design document, section 6.1)
A6: Objective | B6: What it means | C6: Status
A7: Timely | B7: Reflects the queue as it is now, not as it was earlier | C7: Built - how often it runs is not yet confirmed (schedule trigger unverified)
A8: Explainable | B8: A supervisor can see why a queue scored what it did | C8: Built - the score and every component are stored per queue
A9: Comparable across queues | B9: Every queue is scored on the same 0-100 scale | C9: Built
A10: Configurable | B10: Weights, thresholds and bands live in configuration, not in code | C10: Built - values below are the current defaults
A11: Resistant to short-lived spikes | B11: A brief spike should not trigger a reaction | C11: NOT built - each run is a snapshot with no memory of the previous run
A12: Usable by dashboards and the supply calculation | B12: Scores are stored so other components can read them | C12: Partly built - scores are stored; how the dashboard reads them is separate
A14: 2. Configuration - the values that drive the score (edit the mint cells to test alternatives)
A15: Signal | B15: What it measures | C15: Maximum-out threshold | D15: Unit | E15: Weight | F15: Score formula (0 = no pressure, 1 = at the limit) | G15: How far this has been verified
A16: Queue depth | B16: Contacts currently waiting in the queue | C16: 10 | D16: contacts | E16: 0.35 | F16: MIN( contacts waiting ÷ threshold , 1 ) | G16: Verified: 1 waiting contact scored 0.1 in a real Lambda result
A17: Oldest contact age | B17: How long the longest-waiting contact has waited | C17: 300 | D17: seconds | E17: 0.35 | F17: MIN( oldest wait ÷ threshold , 1 ) | G17: Verified at the cap (a 415,122 s wait scored 1.0). Proportional below the cap is assumed
A18: Available agent shortage | B18: Share of staffed agents who are NOT free right now | C18: n/a | D18: ratio 0-1 | E18: 0.2 | F18: IF( staffed <= 0 , 1 , 1 - available ÷ staffed ) | G18: Inferred: reproduces 0 of 0, 1 of 12 and 1 of 14 available. Other ratios assumed proportional
A19: Queued workload | B19: Contacts waiting x average handle time | C19: 1800 | D19: seconds of work | E19: 0.1 | F19: MIN( contacts × handle time ÷ threshold , 1 ) | G19: Verified at one point: 1 contact x 600 s / 1800 = 0.3333 in a real Lambda result
A20: Total weight | E20: =SUM(E16:E19) -> 1 | F20: =IF(ROUND(E20,4)=1,"OK - weights total 1.00","CHECK - weights do not total 1.00") -> OK - weights total 1.00
A22: Other setting | B22: Note | C22: Value | D22: Unit
A23: Default average handle time | B23: Used because handle-time data only refreshes once a day | C23: 600 | D23: seconds
A24: Maximum queue-data age | B24: Older data is flagged STALE and is not scored | C24: 180 | D24: seconds
A25: Score scale | B25: Top of the score range | C25: 100 | D25: points
A27: Band | B27: Meaning | C27: Score from (inclusive)
A28: NORMAL | B28: No unusual pressure | C28: 0
A29: LOW | B29: Building - watch | C29: 25
A30: MEDIUM | B30: Needs attention | C30: 50
A31: HIGH | B31: Significant pressure | C31: 75
A32: CRITICAL | B32: Immediate help needed | C32: 90
A33: The dashboard shows four bands (Normal / Elevated / High / Critical) with different cut-offs from these five - see Open Items #3.
A35: 3. Rules built into the calculation
A36: 1. Score = ROUND( ( depth x w1 + age x w2 + shortage x w3 + workload x w4 ) ÷ total weight × 100 , 2 ).
A37: 2. A queue with nobody waiting always scores 0 - even if it is short of agents.
A38: 3. Queue data older than the maximum age is flagged STALE and is not scored (no number, rather than a wrong one).
A39: 4. Every signal is capped at 1: once a queue reaches a threshold (e.g. 10 contacts or 300 seconds) that signal is 'maxed out' and more adds nothing further.
A40: 5. Only voice queues are scored in this release. Handle time uses a default because live handle-time data refreshes once a day.
A42: 4. Signals the calculation already computes but currently ignores (weight 0)
A43: Signal | B43: Note | C43: Default threshold | D43: Weight
A44: Average handle time | B44: Computed in code, contributes nothing at weight 0 - not modelled here | C44: 600 | D44: 0
A45: Unavailable agent ratio | B45: Computed in code, contributes nothing at weight 0 - not modelled here | C45: 1 | D45: 0
A46: After-contact-work ratio | B46: Computed in code, contributes nothing at weight 0 - not modelled here | C46: 0.5 | D46: 0
...

Sheet Calculation Trace
A1: Calculation Trace - how was this score arrived at?
A2: Pick a row below (the list holds every dashboard row and scenario on the Calculator tab). Each step shows the FORMULA on the left, the VALUE in the middle and the EXPLANATION on the right - with this queue's own numbers filled in.
A4: Choose what to trace
A5: Pick | B5: NSPCC_Tel [dashboard screen 2] | C5: <- choose from the drop-down. To trace your own numbers, overwrite the purple cells for any row on the Calculator tab.
A6: Row # | B6: (position of the picked row on the Calculator tab - used by the formulas below) | C6: =MATCH(B5,Calculator!$A$6:$A$28,0) -> 11
A8: Step | B8: FORMULA (how it is worked out) | C8: VALUE | D8: EXPLANATION
A9: A. Inputs - read from the dashboard row / queue data
A10: In 1 | B10: Queue name (from the dashboard row) | C10: =INDEX(Calculator!$B$6:$B$28,$C$6) -> NSPCC_Tel | D10: ="Instance: "&INDEX(Calculator!$C$6:$C$28,$C$6)&" | Source: "&INDEX(Calculator!$D$6:$D$28,$C$6) -> Instance: macp-uk-buro-dev-connect-1 | Source: Dashboard screen 2
A11: In 2 | B11: Contacts waiting ('In queue' on the dashboard) | C11: =INDEX(Calculator!$F$6:$F$28,$C$6) -> 25 | D11: ="Number of contacts sitting in the queue right now." -> Number of contacts sitting in the queue right now.
A12: In 3 | B12: Oldest contact wait, in seconds ('Oldest' on the dashboard) | C12: =INDEX(Calculator!$G$6:$G$28,$C$6) -> 527 | D12: ="= "&INT(C12/60)&"m "&MOD(C12,60)&"s - how long the longest-waiting contact has waited." -> = 8m 47s - how long the longest-waiting contact has waited.
A13: In 4 | B13: Agents available (first number of 'Available') | C13: =INDEX(Calculator!$H$6:$H$28,$C$6) -> 1 | D13: ="Agents signed in and ready to take a contact right now." -> Agents signed in and ready to take a contact right now.
A14: In 5 | B14: Agents staffed (second number of 'Available') | C14: =INDEX(Calculator!$I$6:$I$28,$C$6) -> 14 | D14: ="Agents signed in to this queue (free or busy)." -> Agents signed in to this queue (free or busy).
A15: In 6 | B15: Age of the queue snapshot, in seconds | C15: =INDEX(Calculator!$E$6:$E$28,$C$6) -> 30 | D15: ="How old the queue data is. Not shown on the dashboard, so 30 s is assumed for dashboard rows." -> How old the queue data is. Not shown on the dashboard, so 30 s is assumed for dashboard rows.
A16: B. Checks before scoring
A17: Check 1 | B17: ="Data freshness: IF( data age > "&'Demand Framework'!$C$24&" s , STALE , OK )"&CHAR(10)&"= IF( "&C15&" > "&'Demand Framework'!$C$24&" , STALE , OK )" -> Data freshness: IF( data age > 180 s , STALE , OK ) = IF( 30 > 180 , STALE , OK ) | C17: =IF(C15>'Demand Framework'!$C$24,"STALE","OK") -> OK | D17: =IF(C17="STALE","The snapshot is older than the limit, so no score is produced (no number is better than a wrong one).","The snapshot is recent enough to score.") -> The snapshot is recent enough to score.
A18: Check 2 | B18: ="Anything waiting? IF( contacts waiting <= 0 , score = 0 )" -> Anything waiting? IF( contacts waiting <= 0 , score = 0 ) | C18: =IF(C11<=0,"NOBODY WAITING","CONTINUE") -> CONTINUE | D18: =IF(C11<=0,"A queue with nobody waiting always scores 0, even if it is short of agents.","There are contacts waiting, so scoring continues.") -> There are contacts waiting, so scoring continues.
A19: C. The four signals - each turned into a 0-1 score
A20: Signal 1 | B20: ="Queue depth score = MIN( contacts waiting ÷ depth threshold , 1 )"&CHAR(10)&"= MIN( "&C11&" ÷ "&'Demand Framework'!$C$16&" , 1 )" -> Queue depth score = MIN( contacts waiting ÷ depth threshold , 1 ) = MIN( 25 ÷ 10 , 1 ) | C20: =MIN(C11/'Demand Framework'!$C$16,1) -> 1 | D20: ="Raw ratio "&TEXT(C11/'Demand Framework'!$C$16,"0.00")&IF(C11/'Demand Framework'!$C$16>=1," - at or above the threshold, so this signal is capped at 1.0 (fully maxed out)."," - below the threshold, so it counts proportionally.") -> Raw ratio 2.50 - at or above the threshold, so this signal is capped at 1.0 (fully maxed out).
A21: Signal 2 | B21: ="Oldest age score = MIN( oldest wait ÷ age threshold , 1 )"&CHAR(10)&"= MIN( "&C12&" ÷ "&'Demand Framework'!$C$17&" , 1 )" -> Oldest age score = MIN( oldest wait ÷ age threshold , 1 ) = MIN( 527 ÷ 300 , 1 ) | C21: =MIN(C12/'Demand Framework'!$C$17,1) -> 1 | D21: ="Raw ratio "&TEXT(C12/'Demand Framework'!$C$17,"0.00")&IF(C12/'Demand Framework'!$C$17>=1," - the longest wait is at or beyond the threshold, so this signal is capped at 1.0."," - below the threshold, so it counts proportionally.") -> Raw ratio 1.76 - the longest wait is at or beyond the threshold, so this signal is capped at 1.0.
A22: Signal 3 | B22: ="Agent shortage = IF( staffed <= 0 , 1 , 1 - available ÷ staffed )"&CHAR(10)&IF(C14<=0,"= 1 (nobody staffed)","= 1 - "&C13&" ÷ "&C14) -> Agent shortage = IF( staffed <= 0 , 1 , 1 - available ÷ staffed ) = 1 - 1 ÷ 14 | C22: =IF(C14<=0,1,MAX(0,MIN(1,1-C13/C14))) -> 0.92857143 | D22: =IF(C14<=0,"Nobody is staffed on this queue, so the shortage is treated as total (1.0).",TEXT(C13/C14,"0.0%")&" of staffed agents are free right now, so "&TEXT(1-C13/C14,"0.0%")&" are not available to take contacts.") -> 7.1% of staffed agents are free right now, so 92.9% are not available to take contacts.
A23: Signal 4a | B23: ="Workload (seconds) = contacts waiting × default handle time"&CHAR(10)&"= "&C11&" × "&'Demand Framework'!$C$23 -> Workload (seconds) = contacts waiting × default handle time = 25 × 600 | C23: =C11*'Demand Framework'!$C$23 -> 15000 | D23: ="An estimate of the work waiting. Handle-time data only refreshes once a day, so the default of "&'Demand Framework'!$C$23&" seconds per contact is used." -> An estimate of the work waiting. Handle-time data only refreshes once a day, so the default of 600 seconds per contact is used.
A24: Signal 4b | B24: ="Workload score = MIN( workload ÷ workload threshold , 1 )"&CHAR(10)&"= MIN( "&C23&" ÷ "&'Demand Framework'!$C$19&" , 1 )" -> Workload score = MIN( workload ÷ workload threshold , 1 ) = MIN( 15000 ÷ 1800 , 1 ) | C24: =MIN(C23/'Demand Framework'!$C$19,1) -> 1 | D24: ="Raw ratio "&TEXT(C23/'Demand Framework'!$C$19,"0.00")&IF(C23/'Demand Framework'!$C$19>=1," - the queued work exceeds the threshold, so this signal is capped at 1.0."," - below the threshold, so it counts proportionally.") -> Raw ratio 8.33 - the queued work exceeds the threshold, so this signal is capped at 1.0.
A25: D. Weighting - each score is multiplied by how much that signal matters
A26: Weight 1 | B26: ="Queue depth contribution = score × weight"&CHAR(10)&"= "&TEXT(C20,"0.000")&" × "&'Demand Framework'!$E$16 -> Queue depth contribution = score × weight = 1.000 × 0.35 | C26: =C20*'Demand Framework'!$E$16 -> 0.35 | D26: =IF(C30=0,"No contribution.",TEXT(C26/C30,"0%")&" of the weighted sum.") -> 36% of the weighted sum.
A27: Weight 2 | B27: ="Oldest age contribution = score × weight"&CHAR(10)&"= "&TEXT(C21,"0.000")&" × "&'Demand Framework'!$E$17 -> Oldest age contribution = score × weight = 1.000 × 0.35 | C27: =C21*'Demand Framework'!$E$17 -> 0.35 | D27: =IF(C30=0,"No contribution.",TEXT(C27/C30,"0%")&" of the weighted sum.") -> 36% of the weighted sum.
A28: Weight 3 | B28: ="Agent shortage contribution = score × weight"&CHAR(10)&"= "&TEXT(C22,"0.000")&" × "&'Demand Framework'!$E$18 -> Agent shortage contribution = score × weight = 0.929 × 0.2 | C28: =C22*'Demand Framework'!$E$18 -> 0.18571429 | D28: =IF(C30=0,"No contribution.",TEXT(C28/C30,"0%")&" of the weighted sum.") -> 19% of the weighted sum.
A29: Weight 4 | B29: ="Queued workload contribution = score × weight"&CHAR(10)&"= "&TEXT(C24,"0.000")&" × "&'Demand Framework'!$E$19 -> Queued workload contribution = score × weight = 1.000 × 0.1 | C29: =C24*'Demand Framework'!$E$19 -> 0.1 | D29: =IF(C30=0,"No contribution.",TEXT(C29/C30,"0%")&" of the weighted sum.") -> 10% of the weighted sum.
A30: Sum | B30: ="Sum of the four contributions"&CHAR(10)&"= "&TEXT(C26,"0.000")&" + "&TEXT(C27,"0.000")&" + "&TEXT(C28,"0.000")&" + "&TEXT(C29,"0.000") -> Sum of the four contributions = 0.350 + 0.350 + 0.186 + 0.100 | C30: =SUM(C26:C29) -> 0.98571429 | D30: ="Adds the four weighted contributions together." -> Adds the four weighted contributions together.
A31: E. Result
A32: Total | B32: ="Weighted total (0-1) = sum ÷ total weight"&CHAR(10)&"= "&TEXT(C30,"0.000")&" ÷ "&'Demand Framework'!$E$20 -> Weighted total (0-1) = sum ÷ total weight = 0.986 ÷ 1 | C32: =C30/'Demand Framework'!$E$20 -> 0.98571429 | D32: =IF(ROUND('Demand Framework'!$E$20,4)=1,"The weights total 1.00, so this equals the sum.","The weights do not total 1.00, so the sum is rescaled.") -> The weights total 1.00, so this equals the sum.
A33: Score | B33: ="Pressure score = ROUND( weighted total × "&'Demand Framework'!$C$25&" , 2 ), unless overridden"&CHAR(10)&IF(C17="STALE","= not scored (stale data)",IF(C11<=0,"= 0 (nobody waiting)","= ROUND( "&TEXT(C32,"0.0000")&" × "&'Demand Framework'!$C$25&" , 2 )")) -> Pressure score = ROUND( weighted total × 100 , 2 ), unless overridden = ROUND( 0.9857 × 100 , 2 ) | C33: =IF(C17="STALE","",IF(C11<=0,0,ROUND(C32*'Demand Framework'!$C$25,2))) -> 98.57 | D33: =IF(C17="STALE","No score is produced from stale data.",IF(C11<=0,"Override: a queue with nobody waiting scores 0, whatever the other signals say.","The final 0-100 pressure score for this queue.")) -> The final 0-100 pressure score for this queue.
A34: Band | B34: ="Band = the highest band whose starting score is at or below the pressure score" -> Band = the highest band whose starting score is at or below the pressure score | C34: =IF(C33="","STALE",INDEX('Demand Framework'!$A$28:$A$32,MATCH(C33,'Demand Framework'!$C$28:$C$32,1))) -> CRITICAL | D34: =IF(C33="","No band without a score.","Score "&TEXT(C33,"0.00")&" falls in "&C34&" (from "&INDEX('Demand Framework'!$C$28:$C$32,MATCH(C33,'Demand Framework'!$C$28:$C$32,1))&IFERROR(" up to just below "&INDEX('Demand Framework'!$C$28:$C$32,MATCH(C33,'Demand Framework'!$C$28:$C$32,1)+1)," upward - the top band")&").") -> Score 98.57 falls in CRITICAL (from 90 upward - the top band).
A35: Driver | B35: ="Biggest driver = the signal with the largest weighted contribution" -> Biggest driver = the signal with the largest weighted contribution | C35: =IF(C33="","",IF(C11<=0,"None - nobody waiting",INDEX('Demand Framework'!$A$16:$A$19,MATCH(MAX(C26:C29),C26:C29,0)))) -> Queue depth | D35: =IF(OR(C33="",C11<=0),"","Contributes "&TEXT(MAX(C26:C29)/'Demand Framework'!$E$20*'Demand Framework'!$C$25,"0.0")&" of the "&TEXT(C33,"0.0")&" points.") -> Contributes 35.0 of the 98.6 points.
A36: F. Checks against other sources
A37: Check 3 | B37: ="Cross-check: the result on the Calculator tab for this row" -> Cross-check: the result on the Calculator tab for this row | C37: =INDEX(Calculator!$T$6:$T$28,$C$6) -> 98.57 | D37: =IF(C37=C33,"Matches this trace.","DOES NOT MATCH the trace - check the Calculator formulas.") -> Matches this trace.
A38: Check 4 | B38: ="Value shown on the dashboard (or by the Lambda) for this row" -> Value shown on the dashboard (or by the Lambda) for this row | C38: =IF(INDEX(Calculator!$V$6:$V$28,$C$6)="","n/a",INDEX(Calculator!$V$6:$V$28,$C$6)) -> 98.6 | D38: =IF(C38="n/a","No dashboard value recorded for this row (illustrative scenario).",IF(C33="","",IF(ABS(C38-C33)<=0.1,"Ties - the dashboard value follows this calculation.","Differs by "&TEXT(C38-C33,"+0.0;-0.0")&" points - the dashboard is not using these defaults (see Open Items #2)."))) -> Ties - the dashboard value follows this calculation.
A40: Reading the trace: grey cells on the left hold the formula in general terms with this queue's numbers underneath; the middle column is the result of that step; the right column says what it means. Purple = inputs from the dashboard row. Yellow = the score and its band.

Sheet Calculator
A1: Calculator - every queue and scenario on one page
A2: Purple cells are live values you can overwrite. Everything else calculates. Rows marked 'Dashboard' were read from the dashboard's Sample data source; the 'Value shown' column is what the dashboard displayed.
A3: Data age is not shown on the dashboard, so 30 seconds is assumed for those rows. Dashboard values were read from photographs, so a digit could be misread - but the differences seen are large and consistent.
E4: Inputs (live data) | K4: Component scores (0-1) | O4: Weighted contribution | S4: Result | V4: Vs dashboard / Lambda
A5: Row label (unique - used by the Trace tab) | B5: Queue | C5: Instance | D5: Data source | E5: Data age (s) | F5: Contacts waiting | G5: Oldest wait (s) | H5: Agents available | I5: Agents staffed | J5: Data status | K5: Queue depth | L5: Oldest age | M5: Agent shortage | N5: Queued workload | O5: Depth x weight | P5: Age x weight | Q5: Shortage x weight | R5: Workload x weight | S5: Weighted total (0-1) | T5: Pressure score (0-100) | U5: Band | V5: Value shown | W5: Difference | X5: Result
A6: The_Scouts_Association_Tel [real Lambda result] | B6: The_Scouts_Association_Tel | C6: macp-uk-buro-dev-connect-1 | D6: Real Lambda result | E6: 30 | F6: 1 | G6: 415122 | H6: 0 | I6: 0 | J6: =IF(E6>'Demand Framework'!$C$24,"STALE","OK") -> OK | K6: =MIN(F6/'Demand Framework'!$C$16,1) -> 0.1 | L6: =MIN(G6/'Demand Framework'!$C$17,1) -> 1 | M6: =IF(I6<=0,1,MAX(0,MIN(1,1-H6/I6))) -> 1 | N6: =MIN(F6*'Demand Framework'!$C$23/'Demand Framework'!$C$19,1) -> 0.33333333 | O6: =K6*'Demand Framework'!$E$16 -> 0.035 | P6: =L6*'Demand Framework'!$E$17 -> 0.35 | Q6: =M6*'Demand Framework'!$E$18 -> 0.2 | R6: =N6*'Demand Framework'!$E$19 -> 0.033333333 | S6: =SUM(O6:R6)/'Demand Framework'!$E$20 -> 0.61833333 | T6: =IF(J6="STALE","",IF(F6<=0,0,ROUND(S6*'Demand Framework'!$C$25,2))) -> 61.83 | U6: =IF(T6="","STALE",INDEX('Demand Framework'!$A$28:$A$32,MATCH(T6,'Demand Framework'!$C$28:$C$32,1))) -> MEDIUM | V6: 61.83 | W6: =IF(OR(V6="",T6=""),"",T6-V6) -> 0 | X6: =IF(V6="","n/a",IF(T6="","",IF(ABS(W6)<=0.1,"Ties","DIFFERS"))) -> Ties
A7: Carers_UK_Tel [dashboard screen 1] | B7: Carers_UK_Tel | C7: macp-uk-buro-dev-connect-1 | D7: Dashboard screen 1 | E7: 30 | F7: 24 | G7: 492 | H7: 0 | I7: 9 | J7: =IF(E7>'Demand Framework'!$C$24,"STALE","OK") -> OK | K7: =MIN(F7/'Demand Framework'!$C$16,1) -> 1 | L7: =MIN(G7/'Demand Framework'!$C$17,1) -> 1 | M7: =IF(I7<=0,1,MAX(0,MIN(1,1-H7/I7))) -> 1 | N7: =MIN(F7*'Demand Framework'!$C$23/'Demand Framework'!$C$19,1) -> 1 | O7: =K7*'Demand Framework'!$E$16 -> 0.35 | P7: =L7*'Demand Framework'!$E$17 -> 0.35 | Q7: =M7*'Demand Framework'!$E$18 -> 0.2 | R7: =N7*'Demand Framework'!$E$19 -> 0.1 | S7: =SUM(O7:R7)/'Demand Framework'!$E$20 -> 1 | T7: =IF(J7="STALE","",IF(F7<=0,0,ROUND(S7*'Demand Framework'!$C$25,2))) -> 100 | U7: =IF(T7="","STALE",INDEX('Demand Framework'!$A$28:$A$32,MATCH(T7,'Demand Framework'!$C$28:$C$32,1))) -> CRITICAL | V7: 100 | W7: =IF(OR(V7="",T7=""),"",T7-V7) -> 0 | X7: =IF(V7="","n/a",IF(T7="","",IF(ABS(W7)<=0.1,"Ties","DIFFERS"))) -> Ties
A8: Gamstop_Betting_Shops_Tel [dashboard screen 1] | B8: Gamstop_Betting_Shops_Tel | C8: macp-uk-gams-dev-connect-1 | D8: Dashboard screen 1 | E8: 30 | F8: 26 | G8: 540 | H8: 1 | I8: 12 | J8: =IF(E8>'Demand Framework'!$C$24,"STALE","OK") -> OK | K8: =MIN(F8/'Demand Framework'!$C$16,1) -> 1 | L8: =MIN(G8/'Demand Framework'!$C$17,1) -> 1 | M8: =IF(I8<=0,1,MAX(0,MIN(1,1-H8/I8))) -> 0.91666667 | N8: =MIN(F8*'Demand Framework'!$C$23/'Demand Framework'!$C$19,1) -> 1 | O8: =K8*'Demand Framework'!$E$16 -> 0.35 | P8: =L8*'Demand Framework'!$E$17 -> 0.35 | Q8: =M8*'Demand Framework'!$E$18 -> 0.18333333 | R8: =N8*'Demand Framework'!$E$19 -> 0.1 | S8: =SUM(O8:R8)/'Demand Framework'!$E$20 -> 0.98333333 | T8: =IF(J8="STALE","",IF(F8<=0,0,ROUND(S8*'Demand Framework'!$C$25,2))) -> 98.33 | U8: =IF(T8="","STALE",INDEX('Demand Framework'!$A$28:$A$32,MATCH(T8,'Demand Framework'!$C$28:$C$32,1))) -> CRITICAL | V8: 98.3 | W8: =IF(OR(V8="",T8=""),"",T8-V8) -> 0.03 | X8: =IF(V8="","n/a",IF(T8="","",IF(ABS(W8)<=0.1,"Ties","DIFFERS"))) -> Ties
A9: NSPCC_Tel [dashboard screen 1] | B9: NSPCC_Tel | C9: macp-uk-buro-dev-connect-1 | D9: Dashboard screen 1 | E9: 30 | F9: 19 | G9: 392 | H9: 1 | I9: 14 | J9: =IF(E9>'Demand Framework'!$C$24,"STALE","OK") -> OK | K9: =MIN(F9/'Demand Framework'!$C$16,1) -> 1 | L9: =MIN(G9/'Demand Framework'!$C$17,1) -> 1 | M9: =IF(I9<=0,1,MAX(0,MIN(1,1-H9/I9))) -> 0.92857143 | N9: =MIN(F9*'Demand Framework'!$C$23/'Demand Framework'!$C$19,1) -> 1 | O9: =K9*'Demand Framework'!$E$16 -> 0.35 | P9: =L9*'Demand Framework'!$E$17 -> 0.35 | Q9: =M9*'Demand Framework'!$E$18 -> 0.18571429 | R9: =N9*'Demand Framework'!$E$19 -> 0.1 | S9: =SUM(O9:R9)/'Demand Framework'!$E$20 -> 0.98571429 | T9: =IF(J9="STALE","",IF(F9<=0,0,ROUND(S9*'Demand Framework'!$C$25,2))) -> 98.57 | U9: =IF(T9="","STALE",INDEX('Demand Framework'!$A$28:$A$32,MATCH(T9,'Demand Framework'!$C$28:$C$32,1))) -> CRITICAL | V9: 90.4 | W9: =IF(OR(V9="",T9=""),"",T9-V9) -> 8.17 | X9: =IF(V9="","n/a",IF(T9="","",IF(ABS(W9)<=0.1,"Ties","DIFFERS"))) -> DIFFERS
A10: Kings_Trust_Anything_Else [dashboard screen 1] | B10: Kings_Trust_Anything_Else | C10: macp-uk-kt-dev-connect-1 | D10: Dashboard screen 1 | E10: 30 | F10: 16 | G10: 327 | H10: 1 | I10: 10 | J10: =IF(E10>'Demand Framework'!$C$24,"STALE","OK") -> OK | K10: =MIN(F10/'Demand Framework'!$C$16,1) -> 1 | L10: =MIN(G10/'Demand Framework'!$C$17,1) -> 1 | M10: =IF(I10<=0,1,MAX(0,MIN(1,1-H10/I10))) -> 0.9 | N10: =MIN(F10*'Demand Framework'!$C$23/'Demand Framework'!$C$19,1) -> 1 | O10: =K10*'Demand Framework'!$E$16 -> 0.35 | P10: =L10*'Demand Framework'!$E$17 -> 0.35 | Q10: =M10*'Demand Framework'!$E$18 -> 0.18 | R10: =N10*'Demand Framework'!$E$19 -> 0.1 | S10: =SUM(O10:R10)/'Demand Framework'!$E$20 -> 0.98 | T10: =IF(J10="STALE","",IF(F10<=0,0,ROUND(S10*'Demand Framework'!$C$25,2))) -> 98 | U10: =IF(T10="","STALE",INDEX('Demand Framework'!$A$28:$A$32,MATCH(T10,'Demand Framework'!$C$28:$C$32,1))) -> CRITICAL | V10: 78.3 | W10: =IF(OR(V10="",T10=""),"",T10-V10) -> 19.7 | X10: =IF(V10="","n/a",IF(T10="","",IF(ABS(W10)<=0.1,"Ties","DIFFERS"))) -> DIFFERS
A11: Employee_Support_Hub_Plus_Tel [dashboard screen 1] | B11: Employee_Support_Hub_Plus_Tel | C11: macp-uk-mind-dev-connect-1 | D11: Dashboard screen 1 | E11: 30 | F11: 8 | G11: 164 | H11: 3 | I11: 13 | J11: =IF(E11>'Demand Framework'!$C$24,"STALE","OK") -> OK | K11: =MIN(F11/'Demand Framework'!$C$16,1) -> 0.8 | L11: =MIN(G11/'Demand Framework'!$C$17,1) -> 0.54666667 | M11: =IF(I11<=0,1,MAX(0,MIN(1,1-H11/I11))) -> 0.76923077 | N11: =MIN(F11*'Demand Framework'!$C$23/'Demand Framework'!$C$19,1) -> 1 | O11: =K11*'Demand Framework'!$E$16 -> 0.28 | P11: =L11*'Demand Framework'!$E$17 -> 0.19133333 | Q11: =M11*'Demand Framework'!$E$18 -> 0.15384615 | R11: =N11*'Demand Framework'!$E$19 -> 0.1 | S11: =SUM(O11:R11)/'Demand Framework'!$E$20 -> 0.72517949 | T11: =IF(J11="STALE","",IF(F11<=0,0,ROUND(S11*'Demand Framework'!$C$25,2))) -> 72.52 | U11: =IF(T11="","STALE",INDEX('Demand Framework'!$A$28:$A$32,MATCH(T11,'Demand Framework'!$C$28:$C$32,1))) -> MEDIUM | V11: 45.6 | W11: =IF(OR(V11="",T11=""),"",T11-V11) -> 26.92 | X11: =IF(V11="","n/a",IF(T11="","",IF(ABS(W11)<=0.1,"Ties","DIFFERS"))) -> DIFFERS
A12: Empathy_Tel [dashboard screen 1] | B12: Empathy_Tel | C12: macp-uk-buro-dev-connect-1 | D12: Dashboard screen 1 | E12: 30 | F12: 6 | G12: 122 | H12: 3 | I12: 11 | J12: =IF(E12>'Demand Framework'!$C$24,"STALE","OK") -> OK | K12: =MIN(F12/'Demand Framework'!$C$16,1) -> 0.6 | L12: =MIN(G12/'Demand Framework'!$C$17,1) -> 0.40666667 | M12: =IF(I12<=0,1,MAX(0,MIN(1,1-H12/I12))) -> 0.72727273 | N12: =MIN(F12*'Demand Framework'!$C$23/'Demand Framework'!$C$19,1) -> 1 | O12: =K12*'Demand Framework'!$E$16 -> 0.21 | P12: =L12*'Demand Framework'!$E$17 -> 0.14233333 | Q12: =M12*'Demand Framework'!$E$18 -> 0.14545455 | R12: =N12*'Demand Framework'!$E$19 -> 0.1 | S12: =SUM(O12:R12)/'Demand Framework'!$E$20 -> 0.59778788 | T12: =IF(J12="STALE","",IF(F12<=0,0,ROUND(S12*'Demand Framework'!$C$25,2))) -> 59.78 | U12: =IF(T12="","STALE",INDEX('Demand Framework'!$A$28:$A$32,MATCH(T12,'Demand Framework'!$C$28:$C$32,1))) -> MEDIUM | V12: 37.1 | W12: =IF(OR(V12="",T12=""),"",T12-V12) -> 22.68 | X12: =IF(V12="","n/a",IF(T12="","",IF(ABS(W12)<=0.1,"Ties","DIFFERS"))) -> DIFFERS
A13: BBC_Tel [dashboard screen 1] | B13: BBC_Tel | C13: macp-uk-buro-dev-connect-1 | D13: Dashboard screen 1 | E13: 30 | F13: 4 | G13: 84 | H13: 3 | I13: 7 | J13: =IF(E13>'Demand Framework'!$C$24,"STALE","OK") -> OK | K13: =MIN(F13/'Demand Framework'!$C$16,1) -> 0.4 | L13: =MIN(G13/'Demand Framework'!$C$17,1) -> 0.28 | M13: =IF(I13<=0,1,MAX(0,MIN(1,1-H13/I13))) -> 0.57142857 | N13: =MIN(F13*'Demand Framework'!$C$23/'Demand Framework'!$C$19,1) -> 1 | O13: =K13*'Demand Framework'!$E$16 -> 0.14 | P13: =L13*'Demand Framework'!$E$17 -> 0.098 | Q13: =M13*'Demand Framework'!$E$18 -> 0.11428571 | R13: =N13*'Demand Framework'!$E$19 -> 0.1 | S13: =SUM(O13:R13)/'Demand Framework'!$E$20 -> 0.45228571 | T13: =IF(J13="STALE","",IF(F13<=0,0,ROUND(S13*'Demand Framework'!$C$25,2))) -> 45.23 | U13: =IF(T13="","STALE",INDEX('Demand Framework'!$A$28:$A$32,MATCH(T13,'Demand Framework'!$C$28:$C$32,1))) -> LOW | V13: 26.7 | W13: =IF(OR(V13="",T13=""),"",T13-V13) -> 18.53 | X13: =IF(V13="","n/a",IF(T13="","",IF(ABS(W13)<=0.1,"Ties","DIFFERS"))) -> DIFFERS
A14: Amica_Tel [dashboard screen 1] | B14: Amica_Tel | C14: macp-uk-kt-dev-connect-1 | D14: Dashboard screen 1 | E14: 30 | F14: 3 | G14: 69 | H14: 2 | I14: 6 | J14: =IF(E14>'Demand Framework'!$C$24,"STALE","OK") -> OK | K14: =MIN(F14/'Demand Framework'!$C$16,1) -> 0.3 | L14: =MIN(G14/'Demand Framework'!$C$17,1) -> 0.23 | M14: =IF(I14<=0,1,MAX(0,MIN(1,1-H14/I14))) -> 0.66666667 | N14: =MIN(F14*'Demand Framework'!$C$23/'Demand Framework'!$C$19,1) -> 1 | O14: =K14*'Demand Framework'!$E$16 -> 0.105 | P14: =L14*'Demand Framework'!$E$17 -> 0.0805 | Q14: =M14*'Demand Framework'!$E$18 -> 0.13333333 | R14: =N14*'Demand Framework'!$E$19 -> 0.1 | S14: =SUM(O14:R14)/'Demand Framework'!$E$20 -> 0.41883333 | T14: =IF(J14="STALE","",IF(F14<=0,0,ROUND(S14*'Demand Framework'!$C$25,2))) -> 41.88 | U14: =IF(T14="","STALE",INDEX('Demand Framework'!$A$28:$A$32,MATCH(T14,'Demand Framework'!$C$28:$C$32,1))) -> LOW | V14: 25.2 | W14: =IF(OR(V14="",T14=""),"",T14-V14) -> 16.68 | X14: =IF(V14="","n/a",IF(T14="","",IF(ABS(W14)<=0.1,"Ties","DIFFERS"))) -> DIFFERS
A15: Gamstop_Online_Update_Current_Exclusion_Tel [dashboard screen 1] | B15: Gamstop_Online_Update_Current_Exclusion_Tel | C15: macp-uk-gams-dev-connect-1 | D15: Dashboard screen 1 | E15: 30 | F15: 3 | G15: 69 | H15: 3 | I15: 8 | J15: =IF(E15>'Demand Framework'!$C$24,"STALE","OK") -> OK | K15: =MIN(F15/'Demand Framework'!$C$16,1) -> 0.3 | L15: =MIN(G15/'Demand Framework'!$C$17,1) -> 0.23 | M15: =IF(I15<=0,1,MAX(0,MIN(1,1-H15/I15))) -> 0.625 | N15: =MIN(F15*'Demand Framework'!$C$23/'Demand Framework'!$C$19,1) -> 1 | O15: =K15*'Demand Framework'!$E$16 -> 0.105 | P15: =L15*'Demand Framework'!$E$17 -> 0.0805 | Q15: =M15*'Demand Framework'!$E$18 -> 0.125 | R15: =N15*'Demand Framework'!$E$19 -> 0.1 | S15: =SUM(O15:R15)/'Demand Framework'!$E$20 -> 0.4105 | T15: =IF(J15="STALE","",IF(F15<=0,0,ROUND(S15*'Demand Framework'!$C$25,2))) -> 41.05 | U15: =IF(T15="","STALE",INDEX('Demand Framework'!$A$28:$A$32,MATCH(T15,'Demand Framework'!$C$28:$C$32,1))) -> LOW | V15: 24.4 | W15: =IF(OR(V15="",T15=""),"",T15-V15) -> 16.65 | X15: =IF(V15="","n/a",IF(T15="","",IF(ABS(W15)<=0.1,"Ties","DIFFERS"))) -> DIFFERS
A16: NSPCC_Tel [dashboard screen 2] | B16: NSPCC_Tel | C16: macp-uk-buro-dev-connect-1 | D16: Dashboard screen 2 | E16: 30 | F16: 25 | G16: 527 | H16: 1 | I16: 14 | J16: =IF(E16>'Demand Framework'!$C$24,"STALE","OK") -> OK | K16: =MIN(F16/'Demand Framework'!$C$16,1) -> 1 | L16: =MIN(G16/'Demand Framework'!$C$17,1) -> 1 | M16: =IF(I16<=0,1,MAX(0,MIN(1,1-H16/I16))) -> 0.92857143 | N16: =MIN(F16*'Demand Framework'!$C$23/'Demand Framework'!$C$19,1) -> 1 | O16: =K16*'Demand Framework'!$E$16 -> 0.35 | P16: =L16*'Demand Framework'!$E$17 -> 0.35 | Q16: =M16*'Demand Framework'!$E$18 -> 0.18571429 | R16: =N16*'Demand Framework'!$E$19 -> 0.1 | S16: =SUM(O16:R16)/'Demand Framework'!$E$20 -> 0.98571429 | T16: =IF(J16="STALE","",IF(F16<=0,0,ROUND(S16*'Demand Framework'!$C$25,2))) -> 98.57 | U16: =IF(T16="","STALE",INDEX('Demand Framework'!$A$28:$A$32,MATCH(T16,'Demand Framework'!$C$28:$C$32,1))) -> CRITICAL | V16: 98.6 | W16: =IF(OR(V16="",T16=""),"",T16-V16) -> -0.03 | X16: =IF(V16="","n/a",IF(T16="","",IF(ABS(W16)<=0.1,"Ties","DIFFERS"))) -> Ties
A17: Employee_Support_Hub_Plus_Tel [dashboard screen 2] | B17: Employee_Support_Hub_Plus_Tel | C17: macp-uk-mind-dev-connect-1 | D17: Dashboard screen 2 | E17: 30 | F17: 20 | G17: 408 | H17: 1 | I17: 13 | J17: =IF(E17>'Demand Framework'!$C$24,"STALE","OK") -> OK | K17: =MIN(F17/'Demand Framework'!$C$16,1) -> 1 | L17: =MIN(G17/'Demand Framework'!$C$17,1) -> 1 | M17: =IF(I17<=0,1,MAX(0,MIN(1,1-H17/I17))) -> 0.92307692 | N17: =MIN(F17*'Demand Framework'!$C$23/'Demand Framework'!$C$19,1) -> 1 | O17: =K17*'Demand Framework'!$E$16 -> 0.35 | P17: =L17*'Demand Framework'!$E$17 -> 0.35 | Q17: =M17*'Demand Framework'!$E$18 -> 0.18461538 | R17: =N17*'Demand Framework'!$E$19 -> 0.1 | S17: =SUM(O17:R17)/'Demand Framework'!$E$20 -> 0.98461538 | T17: =IF(J17="STALE","",IF(F17<=0,0,ROUND(S17*'Demand Framework'!$C$25,2))) -> 98.46 | U17: =IF(T17="","STALE",INDEX('Demand Framework'!$A$28:$A$32,MATCH(T17,'Demand Framework'!$C$28:$C$32,1))) -> CRITICAL | V17: 93.2 | W17: =IF(OR(V17="",T17=""),"",T17-V17) -> 5.26 | X17: =IF(V17="","n/a",IF(T17="","",IF(ABS(W17)<=0.1,"Ties","DIFFERS"))) -> DIFFERS
... A21: Gamstop_Online_Update_Current_Exclusion_Tel [dashboard screen 2] | B21: Gamstop_Online_Update_Current_Exclusion_Tel | C21: macp-uk-gams-dev-connect-1 | D21: Dashboard screen 2 | E21: 30 | F21: 9 | G21: 183 | H21: 2 | I21: 8 | J21: =IF(E21>'Demand Framework'!$C$24,"STALE","OK") -> OK | K21: =MIN(F21/'Demand Framework'!$C$16,1) -> 0.9 | L21: =MIN(G21/'Demand Framework'!$C$17,1) -> 0.61 | M21: =IF(I21<=0,1,MAX(0,MIN(1,1-H21/I21))) -> 0.75 | N21: =MIN(F21*'Demand Framework'!$C$23/'Demand Framework'!$C$19,1) -> 1 | O21: =K21*'Demand Framework'!$E$16 -> 0.315 | P21: =L21*'Demand Framework'!$E$17 -> 0.2135 | Q21: =M21*'Demand Framework'!$E$18 -> 0.15 | R21: =N21*'Demand Framework'!$E$19 -> 0.1 | S21: =SUM(O21:R21)/'Demand Framework'!$E$20 -> 0.7785 | T21: =IF(J21="STALE","",IF(F21<=0,0,ROUND(S21*'Demand Framework'!$C$25,2))) -> 77.85 | U21: =IF(T21="","STALE",INDEX('Demand Framework'!$A$28:$A$32,MATCH(T21,'Demand Framework'!$C$28:$C$32,1))) -> HIGH | V21: 48.8 | W21: =IF(OR(V21="",T21=""),"",T21-V21) -> 29.05 | X21: =IF(V21="","n/a",IF(T21="","",IF(ABS(W21)<=0.1,"Ties","DIFFERS"))) -> DIFFERS
A22: Scenario A - quiet queue [illustrative] | B22: Scenario A - quiet queue | C22: - | D22: Illustrative | E22: 30 | F22: 0 | G22: 0 | H22: 6 | I22: 9 | J22: =IF(E22>'Demand Framework'!$C$24,"STALE","OK") -> OK | K22: =MIN(F22/'Demand Framework'!$C$16,1) -> 0 | L22: =MIN(G22/'Demand Framework'!$C$17,1) -> 0 | M22: =IF(I22<=0,1,MAX(0,MIN(1,1-H22/I22))) -> 0.33333333 | N22: =MIN(F22*'Demand Framework'!$C$23/'Demand Framework'!$C$19,1) -> 0 | O22: =K22*'Demand Framework'!$E$16 -> 0 | P22: =L22*'Demand Framework'!$E$17 -> 0 | Q22: =M22*'Demand Framework'!$E$18 -> 0.066666667 | R22: =N22*'Demand Framework'!$E$19 -> 0 | S22: =SUM(O22:R22)/'Demand Framework'!$E$20 -> 0.066666667 | T22: =IF(J22="STALE","",IF(F22<=0,0,ROUND(S22*'Demand Framework'!$C$25,2))) -> 0 | U22: =IF(T22="","STALE",INDEX('Demand Framework'!$A$28:$A$32,MATCH(T22,'Demand Framework'!$C$28:$C$32,1))) -> NORMAL | W22: =IF(OR(V22="",T22=""),"",T22-V22) | X22: =IF(V22="","n/a",IF(T22="","",IF(ABS(W22)<=0.1,"Ties","DIFFERS"))) -> n/a
A23: Scenario B - one long wait, no cover [illustrative] | B23: Scenario B - one long wait, no cover | C23: - | D23: Illustrative | E23: 30 | F23: 1 | G23: 900 | H23: 0 | I23: 4 | J23: =IF(E23>'Demand Framework'!$C$24,"STALE","OK") -> OK | K23: =MIN(F23/'Demand Framework'!$C$16,1) -> 0.1 | L23: =MIN(G23/'Demand Framework'!$C$17,1) -> 1 | M23: =IF(I23<=0,1,MAX(0,MIN(1,1-H23/I23))) -> 1 | N23: =MIN(F23*'Demand Framework'!$C$23/'Demand Framework'!$C$19,1) -> 0.33333333 | O23: =K23*'Demand Framework'!$E$16 -> 0.035 | P23: =L23*'Demand Framework'!$E$17 -> 0.35 | Q23: =M23*'Demand Framework'!$E$18 -> 0.2 | R23: =N23*'Demand Framework'!$E$19 -> 0.033333333 | S23: =SUM(O23:R23)/'Demand Framework'!$E$20 -> 0.61833333 | T23: =IF(J23="STALE","",IF(F23<=0,0,ROUND(S23*'Demand Framework'!$C$25,2))) -> 61.83 | U23: =IF(T23="","STALE",INDEX('Demand Framework'!$A$28:$A$32,MATCH(T23,'Demand Framework'!$C$28:$C$32,1))) -> MEDIUM | W23: =IF(OR(V23="",T23=""),"",T23-V23) | X23: =IF(V23="","n/a",IF(T23="","",IF(ABS(W23)<=0.1,"Ties","DIFFERS"))) -> n/a
A24: Scenario C - busy but well covered [illustrative] | B24: Scenario C - busy but well covered | C24: - | D24: Illustrative | E24: 30 | F24: 12 | G24: 90 | H24: 6 | I24: 8 | J24: =IF(E24>'Demand Framework'!$C$24,"STALE","OK") -> OK | K24: =MIN(F24/'Demand Framework'!$C$16,1) -> 1 | L24: =MIN(G24/'Demand Framework'!$C$17,1) -> 0.3 | M24: =IF(I24<=0,1,MAX(0,MIN(1,1-H24/I24))) -> 0.25 | N24: =MIN(F24*'Demand Framework'!$C$23/'Demand Framework'!$C$19,1) -> 1 | O24: =K24*'Demand Framework'!$E$16 -> 0.35 | P24: =L24*'Demand Framework'!$E$17 -> 0.105 | Q24: =M24*'Demand Framework'!$E$18 -> 0.05 | R24: =N24*'Demand Framework'!$E$19 -> 0.1 | S24: =SUM(O24:R24)/'Demand Framework'!$E$20 -> 0.605 | T24: =IF(J24="STALE","",IF(F24<=0,0,ROUND(S24*'Demand Framework'!$C$25,2))) -> 60.5 | U24: =IF(T24="","STALE",INDEX('Demand Framework'!$A$28:$A$32,MATCH(T24,'Demand Framework'!$C$28:$C$32,1))) -> MEDIUM | W24: =IF(OR(V24="",T24=""),"",T24-V24) | X24: =IF(V24="","n/a",IF(T24="","",IF(ABS(W24)<=0.1,"Ties","DIFFERS"))) -> n/a
A25: Scenario D - short waits, short-staffed [illustrative] | B25: Scenario D - short waits, short-staffed | C25: - | D25: Illustrative | E25: 30 | F25: 6 | G25: 45 | H25: 1 | I25: 8 | J25: =IF(E25>'Demand Framework'!$C$24,"STALE","OK") -> OK | K25: =MIN(F25/'Demand Framework'!$C$16,1) -> 0.6 | L25: =MIN(G25/'Demand Framework'!$C$17,1) -> 0.15 | M25: =IF(I25<=0,1,MAX(0,MIN(1,1-H25/I25))) -> 0.875 | N25: =MIN(F25*'Demand Framework'!$C$23/'Demand Framework'!$C$19,1) -> 1 | O25: =K25*'Demand Framework'!$E$16 -> 0.21 | P25: =L25*'Demand Framework'!$E$17 -> 0.0525 | Q25: =M25*'Demand Framework'!$E$18 -> 0.175 | R25: =N25*'Demand Framework'!$E$19 -> 0.1 | S25: =SUM(O25:R25)/'Demand Framework'!$E$20 -> 0.5375 | T25: =IF(J25="STALE","",IF(F25<=0,0,ROUND(S25*'Demand Framework'!$C$25,2))) -> 53.75 | U25: =IF(T25="","STALE",INDEX('Demand Framework'!$A$28:$A$32,MATCH(T25,'Demand Framework'!$C$28:$C$32,1))) -> MEDIUM | W25: =IF(OR(V25="",T25=""),"",T25-V25) | X25: =IF(V25="","n/a",IF(T25="","",IF(ABS(W25)<=0.1,"Ties","DIFFERS"))) -> n/a
A26: Scenario E - building steadily [illustrative] | B26: Scenario E - building steadily | C26: - | D26: Illustrative | E26: 30 | F26: 5 | G26: 150 | H26: 2 | I26: 6 | J26: =IF(E26>'Demand Framework'!$C$24,"STALE","OK") -> OK | K26: =MIN(F26/'Demand Framework'!$C$16,1) -> 0.5 | L26: =MIN(G26/'Demand Framework'!$C$17,1) -> 0.5 | M26: =IF(I26<=0,1,MAX(0,MIN(1,1-H26/I26))) -> 0.66666667 | N26: =MIN(F26*'Demand Framework'!$C$23/'Demand Framework'!$C$19,1) -> 1 | O26: =K26*'Demand Framework'!$E$16 -> 0.175 | P26: =L26*'Demand Framework'!$E$17 -> 0.175 | Q26: =M26*'Demand Framework'!$E$18 -> 0.13333333 | R26: =N26*'Demand Framework'!$E$19 -> 0.1 | S26: =SUM(O26:R26)/'Demand Framework'!$E$20 -> 0.58333333 | T26: =IF(J26="STALE","",IF(F26<=0,0,ROUND(S26*'Demand Framework'!$C$25,2))) -> 58.33 | U26: =IF(T26="","STALE",INDEX('Demand Framework'!$A$28:$A$32,MATCH(T26,'Demand Framework'!$C$28:$C$32,1))) -> MEDIUM | W26: =IF(OR(V26="",T26=""),"",T26-V26) | X26: =IF(V26="","n/a",IF(T26="","",IF(ABS(W26)<=0.1,"Ties","DIFFERS"))) -> n/a
A27: Scenario F - everything at its limit [illustrative] | B27: Scenario F - everything at its limit | C27: - | D27: Illustrative | E27: 30 | F27: 15 | G27: 400 | H27: 0 | I27: 5 | J27: =IF(E27>'Demand Framework'!$C$24,"STALE","OK") -> OK | K27: =MIN(F27/'Demand Framework'!$C$16,1) -> 1 | L27: =MIN(G27/'Demand Framework'!$C$17,1) -> 1 | M27: =IF(I27<=0,1,MAX(0,MIN(1,1-H27/I27))) -> 1 | N27: =MIN(F27*'Demand Framework'!$C$23/'Demand Framework'!$C$19,1) -> 1 | O27: =K27*'Demand Framework'!$E$16 -> 0.35 | P27: =L27*'Demand Framework'!$E$17 -> 0.35 | Q27: =M27*'Demand Framework'!$E$18 -> 0.2 | R27: =N27*'Demand Framework'!$E$19 -> 0.1 | S27: =SUM(O27:R27)/'Demand Framework'!$E$20 -> 1 | T27: =IF(J27="STALE","",IF(F27<=0,0,ROUND(S27*'Demand Framework'!$C$25,2))) -> 100 | U27: =IF(T27="","STALE",INDEX('Demand Framework'!$A$28:$A$32,MATCH(T27,'Demand Framework'!$C$28:$C$32,1))) -> CRITICAL | W27: =IF(OR(V27="",T27=""),"",T27-V27) | X27: =IF(V27="","n/a",IF(T27="","",IF(ABS(W27)<=0.1,"Ties","DIFFERS"))) -> n/a
A28: Scenario G - stale data [illustrative] | B28: Scenario G - stale data | C28: - | D28: Illustrative | E28: 300 | F28: 8 | G28: 200 | H28: 2 | I28: 6 | J28: =IF(E28>'Demand Framework'!$C$24,"STALE","OK") -> STALE | K28: =MIN(F28/'Demand Framework'!$C$16,1) -> 0.8 | L28: =MIN(G28/'Demand Framework'!$C$17,1) -> 0.66666667 | M28: =IF(I28<=0,1,MAX(0,MIN(1,1-H28/I28))) -> 0.66666667 | N28: =MIN(F28*'Demand Framework'!$C$23/'Demand Framework'!$C$19,1) -> 1 | O28: =K28*'Demand Framework'!$E$16 -> 0.28 | P28: =L28*'Demand Framework'!$E$17 -> 0.23333333 | Q28: =M28*'Demand Framework'!$E$18 -> 0.13333333 | R28: =N28*'Demand Framework'!$E$19 -> 0.1 | S28: =SUM(O28:R28)/'Demand Framework'!$E$20 -> 0.74666667 | T28: =IF(J28="STALE","",IF(F28<=0,0,ROUND(S28*'Demand Framework'!$C$25,2))) | U28: =IF(T28="","STALE",INDEX('Demand Framework'!$A$28:$A$32,MATCH(T28,'Demand Framework'!$C$28:$C$32,1))) -> STALE | W28: =IF(OR(V28="",T28=""),"",T28-V28) | X28: =IF(V28="","n/a",IF(T28="","",IF(ABS(W28)<=0.1,"Ties","DIFFERS"))) -> n/a
A30: Dashboard rows that tie to this calculation | E30: =SUMPRODUCT((LEFT(D6:D28,9)="Dashboard")*(X6:X28="Ties")) -> 3
A31: Dashboard rows that differ | E31: =SUMPRODUCT((LEFT(D6:D28,9)="Dashboard")*(X6:X28="DIFFERS")) -> 12
A32: Real Lambda result ties | E32: =X6 -> Ties
A34: Reading the comparison: the calculation ties on the dashboard rows where every signal is at its limit, and differs on the rest (the dashboard shows lower scores). That suggests the dashboard's Sample data source uses its own thresholds, weights or generator rather than these defaults. Check with the dashboard's owner before that screen is presented as 'the calculation' (Open Items #2). The real Lambda result (The_Scouts_Association_Tel = 61.83) is reproduced exactly.
A35: Illustrative rows (Scenario A-G) were made up to show how the score behaves: e.g. Scenario B shows a single very old contact with no cover scoring MEDIUM even though volume is one - the same pattern as The_Scouts_Association_Tel.

Sheet Assumptions & Open Items
A1: Assumptions & Open Items - where every number came from, and what is not yet settled
A2: Status key: Default = original system default, never reviewed by the business | Verified = reproduced against real system output | Inferred = deduced from observed results | Reading = taken from a photograph
A4: 1. Sources for every hard-coded value
A5: # | B5: Item | C5: Value | D5: Source | E5: Where used | F5: Status
A6: 1 | B6: Weights: depth / age / shortage / workload | C6: 0.35 / 0.35 / 0.20 / 0.10 | D6: Original starting configuration file supplied at the start of the project (demand_config_example.json). Never validated with the business. | E6: Demand Framework | F6: Default
A7: 2 | B7: Thresholds: contacts / seconds / workload seconds | C7: 10 / 300 / 1800 | D7: Same configuration file. | E7: Demand Framework | F7: Default
A8: 3 | B8: Default handle time | C8: 600 seconds | D8: Same file. Used because handle-time data only refreshes once a day. | E8: Demand Framework | F8: Default
A9: 4 | B9: Maximum queue-data age | C9: 180 seconds | D9: Same file. | E9: Demand Framework | F9: Default
A10: 5 | B10: Pressure bands | C10: 0 / 25 / 50 / 75 / 90 | D10: Same file. The dashboard labels bands differently. | E10: Demand Framework | F10: Default
A11: 6 | B11: Queue-depth and workload formulas | C11: - | D11: Reproduce the component scores in a real Lambda result (depth 0.1, workload 0.3333). | E11: Demand Framework | F11: Verified
A12: 7 | B12: Oldest-age formula | C12: - | D12: Verified only where it is capped at 1.0; proportional below the cap is assumed. | E12: Demand Framework | F12: Inferred
A13: 8 | B13: Agent-shortage formula | C13: 1 - available / staffed | D13: Reproduces 0 of 0 and the 1-of-12 and 1-of-14 dashboard rows that tie. Not read from source code. | E13: Demand Framework | F13: Inferred
A14: 9 | B14: Dashboard values | C14: see Calculator | D14: Read from photographs of the dashboard's Sample data source. | E14: Calculator | F14: Reading
A15: 10 | B15: Real Lambda result | C15: 61.83 | D15: Dry-run output for The_Scouts_Association_Tel: 1 contact, 415,122 s oldest, 0 of 0 agents. | E15: Calculator | F15: Verified
A18: 2. Open items - what needs a decision or a check
A19: # | B19: Item | C19: Owner (suggested) | D19: Why it matters | E19: Where it shows | F19: Type
A20: 1 | B20: Are the weights and thresholds right? | C20: Business / Gemma | D20: They are the original starting defaults and have never been reviewed against operational judgement, unlike the priority framework values. | E20: Demand Framework, section 2 | F20: Decision
A21: 2 | B21: The dashboard's Sample data does not tie to these formulas | C21: Dashboard owner | D21: Only some of the visible dashboard rows reproduce (see Calculator). Sample mode seems to use its own thresholds, weights or generator. | E21: Calculator, columns V-X | F21: Check
A22: 3 | B22: Band names and cut-offs differ between the calculation and the dashboard | C22: Andrew / dashboard owner | D22: Calculation: Normal, Low, Medium, High, Critical (0/25/50/75/90). Dashboard: Normal, Elevated, High, Critical. The same score would carry different labels. | E22: Demand Framework, bands | F22: Check
A23: 4 | B23: Verify the formulas against the Lambda source code | C23: Engineering | D23: The age formula below its cap and the shortage formula for partial availability are assumed from limited real results. | E23: Demand Framework, section 2 | F23: Check
A24: 5 | B24: How often does the calculation run? | C24: Engineering | D24: The design asks for a timely score, but the schedule trigger has not been confirmed. | E24: Demand Framework, section 1 | F24: Check
A25: 6 | B25: No smoothing: a single spike changes the score immediately | C25: Andrew / business | D25: The design (6.5) asks for stability; today each run is a snapshot with no memory of the previous run. | E25: Demand Framework, sections 1 and 5 | F25: Not built
A26: 7 | B26: Nine further signals are calculated but switched off | C26: Business | D26: Abandonment, live handle time, staffing deficit and others exist in code at weight 0. Switching any on needs a business view and reliable, fresher data. | E26: Demand Framework, section 4 | F26: Decision
A27: 8 | B27: Inputs in the design document that are not built | C27: Andrew | D27: Expected near-term capacity, arrival rate and queue operating status have no equivalent in the calculation yet. | E27: Demand Framework, section 5 | F27: Not built
