Workbook

Sheet Overview
A1: Management Console Phase 2 - Calculation Framework
A2: A working model of how the console works out queue pressure, agent availability and where an available agent should go. Draft v0.1 for business review - every calculation is a live formula, so change a value and see the result.
A4: How the three parts fit together
A5: Part | B5: What it answers | C5: Status | D5: Data it uses
A6: Demand Pressure | B6: How busy is each queue right now? Four live signals combine into a 0-100 score and a band. | C6: BUILT and tested | D6: Live data from every queue
A7: Agent Availability | B7: Is this agent in a state we should check, and which queues can they support across every instance? | C7: BUILT and tested | D7: Agent status and routing-profile data
A8: Priority Framework + Priority score | B8: Which queue matters most, based on caller vulnerability, SLA, client value and client journey stage? (Daryll's framework) | C8: BUILT and tested (scoring); Layer 3 not built | D8: Business-set ratings, reviewed occasionally
A9: Supply Calculation (Part B) | B9: When an agent becomes available: which queue, if any, should they move to, after guard rails? | C9: PROPOSED - placeholder values | D9: Combines all of the above
A11: Colour key
A12: Mint fill | B12: Static value set by the business - changes rarely
A13: Purple fill | B13: Dynamic value - comes from live system data
A14: Yellow fill | B14: Key result
A15: Amber fill | B15: Placeholder or not agreed - do not treat as decided
A16: Blue text | B16: An input you can edit (numbers typed in)
A17: Black text | B17: A formula - do not overwrite
A18: Green text | B18: Pulled from another sheet
A20: How to use this workbook
A21: 1. Start with 'Demand Pressure': overwrite the purple cells in the calculator and watch the score and band change.
A22: 2. 'Agent Availability' shows which agent states can trigger a check and how one agent's eligibility is combined across instances.
A23: 3. 'Priority Framework' holds Daryll's rules; 'Supply Calculation' Part A scores queues with them and Part B walks one agent through a decision.
A24: 4. 'Validation' shows how closely the workbook reproduces the real system. 'Sources & Open Items' lists where every number came from and what still needs deciding.
A26: Read this before presenting
A27: - The Demand Pressure weights and thresholds are the original defaults and have not been reviewed by the business (Open Items #2).
A28: - Part B of Supply Calculation is a proposal. The way priority and pressure combine, and every guard-rail value, still need agreeing (Open Items #1, #5-#8).
A29: - The demo front-end's 'Sample' screen does not fully match these formulas - see the Validation tab before showing it alongside this workbook.

Sheet Demand Pressure
A1: Demand Pressure - how busy is each queue right now?
A2: Question this answers: 'Which queues need extra help right now?' Produces a 0-100 score and a band for every voice queue, combining four live signals using agreed weights. Status: BUILT and tested against real data (defaults not yet reviewed by the business).
A4: 1. Configuration - current default values (edit the mint cells to test alternatives)
A5: Factor | B5: What it measures | C5: Maximum-out threshold | D5: Unit | E5: Weight | F5: Status | G5: Value status
A6: Queue depth | B6: Contacts currently waiting in the queue | C6: 10 | D6: contacts | E6: 0.35 | F6: ACTIVE | G6: Default
A7: Oldest contact age | B7: How long the longest-waiting contact has waited | C7: 300 | D7: seconds | E7: 0.35 | F7: ACTIVE | G7: Default
A8: Available agent shortage | B8: Share of staffed agents who are NOT free right now (1 - available / staffed) | C8: n/a | D8: ratio 0-1 | E8: 0.2 | F8: ACTIVE | G8: Default
A9: Queued workload | B9: Contacts waiting x average handle time | C9: 1800 | D9: seconds of work | E9: 0.1 | F9: ACTIVE | G9: Default
A10: Total weight | E10: =SUM(E6:E9) -> 1 | F10: =IF(ROUND(E10,4)=1,"OK","CHECK") -> OK
A12: Other setting | B12: Note | C12: Value | D12: Unit
A13: Default average handle time | B13: Used because handle-time data only refreshes once a day | C13: 600 | D13: seconds
A14: Maximum queue-data age | B14: Older data is flagged STALE and is not scored | C14: 180 | D14: seconds
A15: Score scale | B15: Top of the score range | C15: 100 | D15: points
A17: Pressure band | B17: Meaning | C17: Score from (inclusive)
A18: NORMAL | B18: No unusual pressure | C18: 0
A19: LOW | B19: Building - watch | C19: 25
A20: MEDIUM | B20: Needs attention | C20: 50
A21: HIGH | B21: Significant pressure | C21: 75
A22: CRITICAL | B22: Immediate help needed | C22: 90
A23: The demo front-end shows four bands (Normal / Elevated / High / Critical) with different cut-offs from these five - see Sources & Open Items #3.
A25: Factors the Lambda already calculates but currently SWITCHED OFF (weight 0)
A26: Factor | B26: Note | C26: Default threshold | D26: Weight
A27: Average handle time | B27: Calculated in code, contributes nothing at weight 0 - not modelled here | C27: 600 | D27: 0
A28: Unavailable agent ratio | B28: Calculated in code, contributes nothing at weight 0 - not modelled here | C28: 1 | D28: 0
A29: After-contact-work ratio | B29: Calculated in code, contributes nothing at weight 0 - not modelled here | C29: 0.5 | D29: 0
A30: Agents-on-contact ratio | B30: Calculated in code, contributes nothing at weight 0 - not modelled here | C30: 1 | D30: 0
A31: Staffing deficit (agents) | B31: Calculated in code, contributes nothing at weight 0 - not modelled here | C31: 5 | D31: 0
A32: Abandonment rate (%) | B32: Calculated in code, contributes nothing at weight 0 - not modelled here | C32: 20 | D32: 0
A33: Agent answer rate - minimum (%) | B33: Calculated in code, contributes nothing at weight 0 - not modelled here | C33: 80 | D33: 0
A34: Agent non-response | B34: Calculated in code, contributes nothing at weight 0 - not modelled here | C34: 20 | D34: 0
A35: Maximum queued time (s) | B35: Calculated in code, contributes nothing at weight 0 - not modelled here | C35: 300 | D35: 0
A37: 2. Calculator - purple cells are live values you can overwrite; everything else calculates
A38: How to use: overwrite any purple cell (contacts waiting, oldest wait, agents available, agents staffed). The four scores, weighted contributions, total, band and rank update automatically. Rows 40-42 use real or demo-screen values; rows 43-49 are illustrative scenarios.
D39: Inputs (live data) | J39: Component scores (0 = no pressure, 1 = at limit) | N39: Weighted contribution | S39: Result
A40: Queue / scenario | B40: Instance | C40: Data source | D40: Data age (s) | E40: Contacts waiting | F40: Oldest wait (s) | G40: Agents available | H40: Agents staffed | I40: Data status | J40: Queue depth | K40: Oldest age | L40: Agent shortage | M40: Queued workload | N40: Depth x weight | O40: Age x weight | P40: Shortage x weight | Q40: Workload x weight | R40: Weighted total (0-1) | S40: Pressure score (0-100) | T40: Band | U40: Rank
A41: The_Scouts_Association_Tel | B41: macp-uk-buro-dev-connect-1 | C41: Real Lambda result | D41: 30 | E41: 1 | F41: 415122 | G41: 0 | H41: 0 | I41: =IF(D41>$C$14,"STALE","OK") -> OK | J41: =MIN(E41/$C$6,1) -> 0.1 | K41: =MIN(F41/$C$7,1) -> 1 | L41: =IF(H41<=0,1,MAX(0,MIN(1,1-G41/H41))) -> 1 | M41: =MIN(E41*$C$13/$C$9,1) -> 0.33333333 | N41: =J41*$E$6 -> 0.035 | O41: =K41*$E$7 -> 0.35 | P41: =L41*$E$8 -> 0.2 | Q41: =M41*$E$9 -> 0.033333333 | R41: =SUM(N41:Q41)/$E$10 -> 0.61833333 | S41: =IF(I41="STALE","",IF(E41<=0,0,ROUND(R41*$C$15,2))) -> 61.83 | T41: =IF(S41="","STALE",INDEX($A$18:$A$22,MATCH(S41,$C$18:$C$22,1))) -> MEDIUM | U41: =IF(S41="","",RANK(S41,$S$41:$S$50)) -> 4
A42: NSPCC_Tel | B42: macp-uk-buro-dev-connect-1 | C42: Demo screen (ties) | D42: 30 | E42: 25 | F42: 527 | G42: 1 | H42: 14 | I42: =IF(D42>$C$14,"STALE","OK") -> OK | J42: =MIN(E42/$C$6,1) -> 1 | K42: =MIN(F42/$C$7,1) -> 1 | L42: =IF(H42<=0,1,MAX(0,MIN(1,1-G42/H42))) -> 0.92857143 | M42: =MIN(E42*$C$13/$C$9,1) -> 1 | N42: =J42*$E$6 -> 0.35 | O42: =K42*$E$7 -> 0.35 | P42: =L42*$E$8 -> 0.18571429 | Q42: =M42*$E$9 -> 0.1 | R42: =SUM(N42:Q42)/$E$10 -> 0.98571429 | S42: =IF(I42="STALE","",IF(E42<=0,0,ROUND(R42*$C$15,2))) -> 98.57 | T42: =IF(S42="","STALE",INDEX($A$18:$A$22,MATCH(S42,$C$18:$C$22,1))) -> CRITICAL | U42: =IF(S42="","",RANK(S42,$S$41:$S$50)) -> 3
A43: Carers_UK_Tel | B43: macp-uk-buro-dev-connect-1 | C43: Demo screen (ties) | D43: 30 | E43: 24 | F43: 492 | G43: 0 | H43: 9 | I43: =IF(D43>$C$14,"STALE","OK") -> OK | J43: =MIN(E43/$C$6,1) -> 1 | K43: =MIN(F43/$C$7,1) -> 1 | L43: =IF(H43<=0,1,MAX(0,MIN(1,1-G43/H43))) -> 1 | M43: =MIN(E43*$C$13/$C$9,1) -> 1 | N43: =J43*$E$6 -> 0.35 | O43: =K43*$E$7 -> 0.35 | P43: =L43*$E$8 -> 0.2 | Q43: =M43*$E$9 -> 0.1 | R43: =SUM(N43:Q43)/$E$10 -> 1 | S43: =IF(I43="STALE","",IF(E43<=0,0,ROUND(R43*$C$15,2))) -> 100 | T43: =IF(S43="","STALE",INDEX($A$18:$A$22,MATCH(S43,$C$18:$C$22,1))) -> CRITICAL | U43: =IF(S43="","",RANK(S43,$S$41:$S$50)) -> 1
A44: Scenario A - quiet queue | B44: - | C44: Illustrative | D44: 30 | E44: 0 | F44: 0 | G44: 6 | H44: 9 | I44: =IF(D44>$C$14,"STALE","OK") -> OK | J44: =MIN(E44/$C$6,1) -> 0 | K44: =MIN(F44/$C$7,1) -> 0 | L44: =IF(H44<=0,1,MAX(0,MIN(1,1-G44/H44))) -> 0.33333333 | M44: =MIN(E44*$C$13/$C$9,1) -> 0 | N44: =J44*$E$6 -> 0 | O44: =K44*$E$7 -> 0 | P44: =L44*$E$8 -> 0.066666667 | Q44: =M44*$E$9 -> 0 | R44: =SUM(N44:Q44)/$E$10 -> 0.066666667 | S44: =IF(I44="STALE","",IF(E44<=0,0,ROUND(R44*$C$15,2))) -> 0 | T44: =IF(S44="","STALE",INDEX($A$18:$A$22,MATCH(S44,$C$18:$C$22,1))) -> NORMAL | U44: =IF(S44="","",RANK(S44,$S$41:$S$50)) -> 9
A45: Scenario B - one long wait, no cover | B45: - | C45: Illustrative | D45: 30 | E45: 1 | F45: 900 | G45: 0 | H45: 4 | I45: =IF(D45>$C$14,"STALE","OK") -> OK | J45: =MIN(E45/$C$6,1) -> 0.1 | K45: =MIN(F45/$C$7,1) -> 1 | L45: =IF(H45<=0,1,MAX(0,MIN(1,1-G45/H45))) -> 1 | M45: =MIN(E45*$C$13/$C$9,1) -> 0.33333333 | N45: =J45*$E$6 -> 0.035 | O45: =K45*$E$7 -> 0.35 | P45: =L45*$E$8 -> 0.2 | Q45: =M45*$E$9 -> 0.033333333 | R45: =SUM(N45:Q45)/$E$10 -> 0.61833333 | S45: =IF(I45="STALE","",IF(E45<=0,0,ROUND(R45*$C$15,2))) -> 61.83 | T45: =IF(S45="","STALE",INDEX($A$18:$A$22,MATCH(S45,$C$18:$C$22,1))) -> MEDIUM | U45: =IF(S45="","",RANK(S45,$S$41:$S$50)) -> 4
...

Sheet Agent Availability
A1: Agent Availability - who can be considered for a move?
A2: Questions this answers: 'Is this agent in a state where we should even check?' and 'Which queues is this agent allowed to support, across every instance?' Status: BUILT (agent data capture and eligibility lookup are deployed and tested).
A4: 1. Agent states - which states can trigger an allocation check?
A5: Agent state | B5: What it means | C5: Immediate capacity? | D5: Can trigger an allocation check? | G5: Source
A6: Available (routable) | B6: Signed in, ready, not handling a contact | C6: Yes | D6: YES | G6: HLD 2.1 - allocation decisions start only when an agent reaches an eligible available state
A7: On a contact | B7: Handling a live contact | C7: No (near-term) | D7: NO | G7: HLD 2 - agents are never moved mid-contact; HLD 6.2 - counts as near-term capacity
A8: After-contact work | B8: Finishing notes after a contact | C8: No (near-term) | D8: NO | G8: HLD 6.2 - occupied agents remain near-term capacity
A9: Signed in, not routable | B9: e.g. break, lunch, training | C9: No | D9: NO | G9: HLD 6.2 - unavailable agents are not immediate capacity
A10: Offline | B10: Not signed in | C10: No | D10: NO | G10: -
A12: Try it - example agent's current state (choose): | B12: Available (routable)
A13: Allocation check triggered? | B13: =INDEX($D$6:$D$10,MATCH($B$12,$A$6:$A$10,0)) -> YES
A15: 2. Queue availability - how the 'agent shortage' score is built (feeds Demand Pressure)
A16: Queue (illustrative) | B16: Note | C16: Agents staffed | D16: Agents available | E16: On a contact | F16: After-contact work | G16: Available % | H16: Shortage score | I16: Note
A17: Example 1 | B17: No agents free | C17: 9 | D17: 0 | E17: 7 | F17: 2 | G17: =IF(C17<=0,"n/a",D17/C17) -> 0 | H17: =IF(C17<=0,1,MAX(0,MIN(1,1-D17/C17))) -> 1 | I17: On contact and after-contact work are shown for context only - not scored
A18: Example 2 | B18: Thin cover (like NSPCC in the demo) | C18: 14 | D18: 1 | E18: 11 | F18: 2 | G18: =IF(C18<=0,"n/a",D18/C18) -> 0.071428571 | H18: =IF(C18<=0,1,MAX(0,MIN(1,1-D18/C18))) -> 0.92857143
A19: Example 3 | B19: Half the agents free | C19: 8 | D19: 4 | E19: 3 | F19: 1 | G19: =IF(C19<=0,"n/a",D19/C19) -> 0.5 | H19: =IF(C19<=0,1,MAX(0,MIN(1,1-D19/C19))) -> 0.5
A20: Example 4 | B20: Well covered | C20: 10 | D20: 8 | E20: 2 | F20: 0 | G20: =IF(C20<=0,"n/a",D20/C20) -> 0.8 | H20: =IF(C20<=0,1,MAX(0,MIN(1,1-D20/C20))) -> 0.2
A21: Example 5 | B21: Nobody signed in | C21: 0 | D21: 0 | E21: 0 | F21: 0 | G21: =IF(C21<=0,"n/a",D21/C21) -> n/a | H21: =IF(C21<=0,1,MAX(0,MIN(1,1-D21/C21))) -> 1
A22: Shortage score = 1 - available / staffed; if nobody is staffed the score is 1 (matches a real record where 0 of 0 agents scored 1). It is weighted at 0.20 in Demand Pressure. Real queue data carries these five counts per queue: available, on contact, after-contact work, online and staffed.
A24: 3. Cross-instance eligibility - one agent, several routing profiles
A25: An agent's eligible queues = every queue in ANY of their routing profiles, across every instance (combined and de-duplicated). Enter 1 where that profile includes the queue. In the real test data one agent holds four routing profiles across four instances at once - which is why eligibility must combine all of an agent's records.
A26: Queue | B26: Instance / group | C26: Profile on instance A | D26: Profile on instance B | E26: Profile on instance C | F26: Profile on instance D | G26: Eligible?
A27: Empathy_Tel | B27: Bureau | C27: 1 | D27: 0 | E27: 0 | F27: 0 | G27: =IF(SUM(C27:F27)>0,"Yes","No") -> Yes
A28: Al_Jazeera_Tel | B28: Bureau | C28: 1 | D28: 0 | E28: 0 | F28: 0 | G28: =IF(SUM(C28:F28)>0,"Yes","No") -> Yes
A29: Construction_Worker_Charitable_Trust_Tel | B29: Bureau | C29: 1 | D29: 0 | E29: 0 | F29: 0 | G29: =IF(SUM(C29:F29)>0,"Yes","No") -> Yes
A30: Life_and_Progress_Assistance_Programme_Tel | B30: Bureau | C30: 1 | D30: 0 | E30: 0 | F30: 0 | G30: =IF(SUM(C30:F30)>0,"Yes","No") -> Yes
A31: Hourglass_Tel | B31: Bureau | C31: 0 | D31: 0 | E31: 0 | F31: 0 | G31: =IF(SUM(C31:F31)>0,"Yes","No") -> No
A32: Mind_Welfare_Tel | B32: Mind (dedicated) | C32: 0 | D32: 0 | E32: 0 | F32: 0 | G32: =IF(SUM(C32:F32)>0,"Yes","No") -> No
A33: Gamstop_Betting_Shops_Tel | B33: GamStop (dedicated) | C33: 0 | D33: 1 | E33: 0 | F33: 0 | G33: =IF(SUM(C33:F33)>0,"Yes","No") -> Yes
A34: Evergreen_Consumer_Care_Tel | B34: Evergreen (dedicated) | C34: 0 | D34: 0 | E34: 0 | F34: 0 | G34: =IF(SUM(C34:F34)>0,"Yes","No") -> No
A35: Eligible queues (count) | G35: =COUNTIF(G27:G34,"Yes") -> 5
A36: Queue names and ratings are real (from the business's queue list); which agent holds which profile is illustrative. In the live system this comes from each agent's routing profile, captured from Connect agent events. Routing-profile membership is the only eligibility test in this release - no separate skills score (HLD 2.1).

Sheet Priority Framework
A1: Priority Framework - the business rules for 'who should be answered first?'
A2: Transcribed from Daryll's Framework v2 tab (screenshots, Sept 2026) - please verify against the live sheet before sign-off. Mint = static value set by the business and reviewed occasionally. Purple = dynamic (comes from live data) and NOT yet wired into any calculation.
A4: Layer 1 - Customer Priority: Caller vulnerability (static)
A5: Vulnerability tier | B5: Treatment | C5: Score
A6: Critical Vulnerability | B6: Mandatory Priority | C6: 50
A7: High Vulnerability | B7: Mandatory Priority | C7: 40
A8: Moderate Vulnerability | B8: Continues through Layers 1, 2 and guard rails | C8: 13
A9: Low Vulnerability | B9: Continues through Layers 1, 2 and guard rails | C9: 10
A10: No Known Vulnerability | B10: Continues through Layers 1, 2 and guard rails | C10: 0
A11: Mandatory Priority threshold (score at or above) | B11: Skips Client Priority, Operational Modifiers and Bureau Optimisation; only waiting time sequences these contacts | C11: 40
A13: Layer 2 - Client Priority (static). Factored value = level x weight
A14: SLA Tier - weight in Layer 2 | C14: 0.5
A15: Tier | C15: Level (1-5) | D15: Factored value (level x weight)
A16: VIP | C16: 5 | D16: =C16*$C$14 -> 2.5
A17: High | C17: 4 | D17: =C17*$C$14 -> 2
A18: Standard | C18: 3 | D18: =C18*$C$14 -> 1.5
A19: Flexible | C19: 2 | D19: =C19*$C$14 -> 1
A20: Best Endeavours | C20: 1 | D20: =C20*$C$14 -> 0.5
A22: Client Value - weight in Layer 2 | C22: 0.3
A23: Tier | C23: Level (1-5) | D23: Factored value (level x weight)
A24: Strategic / VIP | C24: 5 | D24: =C24*$C$22 -> 1.5
A25: High Value | C25: 4 | D25: =C25*$C$22 -> 1.2
A26: Core Value | C26: 3 | D26: =C26*$C$22 -> 0.9
A27: Developing Value | C27: 2 | D27: =C27*$C$22 -> 0.6
A28: Low Value / Transactional | C28: 1 | D28: =C28*$C$22 -> 0.3
A30: Client Journey Stage - weight in Layer 2 | C30: 0.2
A31: Tier | C31: Level (1-5) | D31: Factored value (level x weight)
A32: Onboarding / New Customer (0-90 Days) | C32: 5 | D32: =C32*$C$30 -> 1
A33: Renewal / At-Risk of Churn | C33: 4 | D33: =C33*$C$30 -> 0.8
A34: Existing Customer - High Interest / Low Risk | C34: 3 | D34: =C34*$C$30 -> 0.6
A35: Existing Customer - Low Interest / Low Risk | C35: 2 | D35: =C35*$C$30 -> 0.4
A36: Exiting Customer | C36: 1 | D36: =C36*$C$30 -> 0.2
A38: Layer 2 weights total | C38: =C14+C22+C30 -> 1 | D38: =IF(ROUND(C38,4)=1,"OK - totals 100%","CHECK - weights do not total 100%") -> OK - totals 100%
A39: Priority score (as in the CX Rules Matrix): IF vulnerability score >= threshold THEN score = vulnerability score, OTHERWISE score = vulnerability score x SLA factored x Client Value factored x Journey Stage factored. Note: this is multiplicative. The worked example discussed on the call (85 vs 120) sounded additive - see Sources & Open Items #9.
A41: Layer 1 (dynamic) - Waiting time / queue age: defined but NOT yet wired into any calculation
A42: Tier | B42: Waiting-time definition | C42: Level
A43: Critical Wait | B43: Exceeded threshold boundary (TB) by more than 100% | C43: 5
A44: High Wait | B44: Exceeded TB by 50-100% | C44: 4
A45: Approaching Breach | B45: 75-100% of TB elapsed | C45: 3
A46: Standard Wait | B46: 25-75% of TB elapsed | C46: 2
...

Sheet Supply Calculation
A1: Supply Calculation - where should an available agent go?
A2: Flow: 1 Is the agent in a state we should check? -> 2 Which queues can they support? -> 3 Which of those are under pressure? -> 4 Rank them by business priority -> 5 Apply the guard rails -> 6 Decide: MOVE or REMAIN.
A3: STATUS: Part A (priority score) is BUILT and tested against Daryll's spreadsheet. Part B (selection, guard rails, decision) is a PROPOSED design using PLACEHOLDER values - nothing in Part B has been agreed or built yet. It is here so the business can react to a concrete example.
A5: Part A - Static priority score per queue (built and tested - mirrors Daryll's CX Rules Matrix)
A6: Queue | B6: Group | C6: Vulnerability tier | D6: SLA tier | E6: Client value tier | F6: Journey stage | G6: Vuln. score | H6: SLA factored | I6: Client value factored | J6: Journey factored | K6: Priority score | L6: Mandatory priority? | M6: Total per CX Rules Matrix (typed) | N6: Ties to matrix? | O6: Rank by raw score | P6: Rank, mandatory first | Q6: Ranking key
A7: Empathy_Tel | B7: Bureau 1 | C7: Moderate Vulnerability | D7: Standard | E7: Core Value | F7: Exiting Customer | G7: =INDEX('Priority Framework'!$C$6:$C$10,MATCH(C7,'Priority Framework'!$A$6:$A$10,0)) -> 13 | H7: =INDEX('Priority Framework'!$D$16:$D$20,MATCH(D7,'Priority Framework'!$A$16:$A$20,0)) -> 1.5 | I7: =INDEX('Priority Framework'!$D$24:$D$28,MATCH(E7,'Priority Framework'!$A$24:$A$28,0)) -> 0.9 | J7: =INDEX('Priority Framework'!$D$32:$D$36,MATCH(F7,'Priority Framework'!$A$32:$A$36,0)) -> 0.2 | K7: =IF(G7>='Priority Framework'!$C$11,G7,ROUND(G7*H7*I7*J7,2)) -> 3.51 | L7: =IF(G7>='Priority Framework'!$C$11,"YES","No") -> No | M7: 3.51 | N7: =IF(M7="","n/a",IF(ABS(K7-M7)<0.005,"Ties","DIFFERS")) -> Ties | O7: =RANK(K7,$K$7:$K$15) -> 6 | P7: =RANK(Q7,$Q$7:$Q$15) -> 6 | Q7: =IF(L7="YES",1000,0)+K7 -> 3.51
A8: Al_Jazeera_Tel | B8: Bureau 1 | C8: Moderate Vulnerability | D8: Standard | E8: Core Value | F8: Exiting Customer | G8: =INDEX('Priority Framework'!$C$6:$C$10,MATCH(C8,'Priority Framework'!$A$6:$A$10,0)) -> 13 | H8: =INDEX('Priority Framework'!$D$16:$D$20,MATCH(D8,'Priority Framework'!$A$16:$A$20,0)) -> 1.5 | I8: =INDEX('Priority Framework'!$D$24:$D$28,MATCH(E8,'Priority Framework'!$A$24:$A$28,0)) -> 0.9 | J8: =INDEX('Priority Framework'!$D$32:$D$36,MATCH(F8,'Priority Framework'!$A$32:$A$36,0)) -> 0.2 | K8: =IF(G8>='Priority Framework'!$C$11,G8,ROUND(G8*H8*I8*J8,2)) -> 3.51 | L8: =IF(G8>='Priority Framework'!$C$11,"YES","No") -> No | M8: 3.51 | N8: =IF(M8="","n/a",IF(ABS(K8-M8)<0.005,"Ties","DIFFERS")) -> Ties | O8: =RANK(K8,$K$7:$K$15) -> 6 | P8: =RANK(Q8,$Q$7:$Q$15) -> 6 | Q8: =IF(L8="YES",1000,0)+K8 -> 3.51
A9: Construction_Worker_Charitable_Trust_Tel | B9: Bureau 1 | C9: Moderate Vulnerability | D9: High | E9: Core Value | F9: Existing Customer - High Interest / Low Risk | G9: =INDEX('Priority Framework'!$C$6:$C$10,MATCH(C9,'Priority Framework'!$A$6:$A$10,0)) -> 13 | H9: =INDEX('Priority Framework'!$D$16:$D$20,MATCH(D9,'Priority Framework'!$A$16:$A$20,0)) -> 2 | I9: =INDEX('Priority Framework'!$D$24:$D$28,MATCH(E9,'Priority Framework'!$A$24:$A$28,0)) -> 0.9 | J9: =INDEX('Priority Framework'!$D$32:$D$36,MATCH(F9,'Priority Framework'!$A$32:$A$36,0)) -> 0.6 | K9: =IF(G9>='Priority Framework'!$C$11,G9,ROUND(G9*H9*I9*J9,2)) -> 14.04 | L9: =IF(G9>='Priority Framework'!$C$11,"YES","No") -> No | M9: 14.04 | N9: =IF(M9="","n/a",IF(ABS(K9-M9)<0.005,"Ties","DIFFERS")) -> Ties | O9: =RANK(K9,$K$7:$K$15) -> 5 | P9: =RANK(Q9,$Q$7:$Q$15) -> 5 | Q9: =IF(L9="YES",1000,0)+K9 -> 14.04
A10: Life_and_Progress_Assistance_Programme_Tel | B10: Bureau 1 | C10: Moderate Vulnerability | D10: Standard | E10: Core Value | F10: Onboarding / New Customer (0-90 Days) | G10: =INDEX('Priority Framework'!$C$6:$C$10,MATCH(C10,'Priority Framework'!$A$6:$A$10,0)) -> 13 | H10: =INDEX('Priority Framework'!$D$16:$D$20,MATCH(D10,'Priority Framework'!$A$16:$A$20,0)) -> 1.5 | I10: =INDEX('Priority Framework'!$D$24:$D$28,MATCH(E10,'Priority Framework'!$A$24:$A$28,0)) -> 0.9 | J10: =INDEX('Priority Framework'!$D$32:$D$36,MATCH(F10,'Priority Framework'!$A$32:$A$36,0)) -> 1 | K10: =IF(G10>='Priority Framework'!$C$11,G10,ROUND(G10*H10*I10*J10,2)) -> 17.55 | L10: =IF(G10>='Priority Framework'!$C$11,"YES","No") -> No | M10: 17.55 | N10: =IF(M10="","n/a",IF(ABS(K10-M10)<0.005,"Ties","DIFFERS")) -> Ties | O10: =RANK(K10,$K$7:$K$15) -> 4 | P10: =RANK(Q10,$Q$7:$Q$15) -> 4 | Q10: =IF(L10="YES",1000,0)+K10 -> 17.55
A11: Hourglass_Tel | B11: Bureau 1 | C11: High Vulnerability | D11: Standard | E11: Core Value | F11: Exiting Customer | G11: =INDEX('Priority Framework'!$C$6:$C$10,MATCH(C11,'Priority Framework'!$A$6:$A$10,0)) -> 40 | H11: =INDEX('Priority Framework'!$D$16:$D$20,MATCH(D11,'Priority Framework'!$A$16:$A$20,0)) -> 1.5 | I11: =INDEX('Priority Framework'!$D$24:$D$28,MATCH(E11,'Priority Framework'!$A$24:$A$28,0)) -> 0.9 | J11: =INDEX('Priority Framework'!$D$32:$D$36,MATCH(F11,'Priority Framework'!$A$32:$A$36,0)) -> 0.2 | K11: =IF(G11>='Priority Framework'!$C$11,G11,ROUND(G11*H11*I11*J11,2)) -> 40 | L11: =IF(G11>='Priority Framework'!$C$11,"YES","No") -> YES | M11: 40 | N11: =IF(M11="","n/a",IF(ABS(K11-M11)<0.005,"Ties","DIFFERS")) -> Ties | O11: =RANK(K11,$K$7:$K$15) -> 2 | P11: =RANK(Q11,$Q$7:$Q$15) -> 1 | Q11: =IF(L11="YES",1000,0)+K11 -> 1040
A12: Mind_Welfare_Tel | B12: Mind (dedicated) | C12: High Vulnerability | D12: Standard | E12: Core Value | F12: Exiting Customer | G12: =INDEX('Priority Framework'!$C$6:$C$10,MATCH(C12,'Priority Framework'!$A$6:$A$10,0)) -> 40 | H12: =INDEX('Priority Framework'!$D$16:$D$20,MATCH(D12,'Priority Framework'!$A$16:$A$20,0)) -> 1.5 | I12: =INDEX('Priority Framework'!$D$24:$D$28,MATCH(E12,'Priority Framework'!$A$24:$A$28,0)) -> 0.9 | J12: =INDEX('Priority Framework'!$D$32:$D$36,MATCH(F12,'Priority Framework'!$A$32:$A$36,0)) -> 0.2 | K12: =IF(G12>='Priority Framework'!$C$11,G12,ROUND(G12*H12*I12*J12,2)) -> 40 | L12: =IF(G12>='Priority Framework'!$C$11,"YES","No") -> YES | M12: 40 | N12: =IF(M12="","n/a",IF(ABS(K12-M12)<0.005,"Ties","DIFFERS")) -> Ties | O12: =RANK(K12,$K$7:$K$15) -> 2 | P12: =RANK(Q12,$Q$7:$Q$15) -> 1 | Q12: =IF(L12="YES",1000,0)+K12 -> 1040
A13: Gamstop_Betting_Shops_Tel | B13: GamStop (dedicated) | C13: Low Vulnerability | D13: Standard | E13: Core Value | F13: Exiting Customer | G13: =INDEX('Priority Framework'!$C$6:$C$10,MATCH(C13,'Priority Framework'!$A$6:$A$10,0)) -> 10 | H13: =INDEX('Priority Framework'!$D$16:$D$20,MATCH(D13,'Priority Framework'!$A$16:$A$20,0)) -> 1.5 | I13: =INDEX('Priority Framework'!$D$24:$D$28,MATCH(E13,'Priority Framework'!$A$24:$A$28,0)) -> 0.9 | J13: =INDEX('Priority Framework'!$D$32:$D$36,MATCH(F13,'Priority Framework'!$A$32:$A$36,0)) -> 0.2 | K13: =IF(G13>='Priority Framework'!$C$11,G13,ROUND(G13*H13*I13*J13,2)) -> 2.7 | L13: =IF(G13>='Priority Framework'!$C$11,"YES","No") -> No | M13: 2.7 | N13: =IF(M13="","n/a",IF(ABS(K13-M13)<0.005,"Ties","DIFFERS")) -> Ties | O13: =RANK(K13,$K$7:$K$15) -> 8 | P13: =RANK(Q13,$Q$7:$Q$15) -> 8 | Q13: =IF(L13="YES",1000,0)+K13 -> 2.7
A14: Evergreen_Consumer_Care_Tel | B14: Evergreen (dedicated) | C14: No Known Vulnerability | D14: Standard | E14: Core Value | F14: Exiting Customer | G14: =INDEX('Priority Framework'!$C$6:$C$10,MATCH(C14,'Priority Framework'!$A$6:$A$10,0)) -> 0 | H14: =INDEX('Priority Framework'!$D$16:$D$20,MATCH(D14,'Priority Framework'!$A$16:$A$20,0)) -> 1.5 | I14: =INDEX('Priority Framework'!$D$24:$D$28,MATCH(E14,'Priority Framework'!$A$24:$A$28,0)) -> 0.9 | J14: =INDEX('Priority Framework'!$D$32:$D$36,MATCH(F14,'Priority Framework'!$A$32:$A$36,0)) -> 0.2 | K14: =IF(G14>='Priority Framework'!$C$11,G14,ROUND(G14*H14*I14*J14,2)) -> 0 | L14: =IF(G14>='Priority Framework'!$C$11,"YES","No") -> No | M14: 0 | N14: =IF(M14="","n/a",IF(ABS(K14-M14)<0.005,"Ties","DIFFERS")) -> Ties | O14: =RANK(K14,$K$7:$K$15) -> 9 | P14: =RANK(Q14,$Q$7:$Q$15) -> 9 | Q14: =IF(L14="YES",1000,0)+K14 -> 0
A15: Edge case (illustrative only) | B15: - | C15: Moderate Vulnerability | D15: VIP | E15: Strategic / VIP | F15: Onboarding / New Customer (0-90 Days) | G15: =INDEX('Priority Framework'!$C$6:$C$10,MATCH(C15,'Priority Framework'!$A$6:$A$10,0)) -> 13 | H15: =INDEX('Priority Framework'!$D$16:$D$20,MATCH(D15,'Priority Framework'!$A$16:$A$20,0)) -> 2.5 | I15: =INDEX('Priority Framework'!$D$24:$D$28,MATCH(E15,'Priority Framework'!$A$24:$A$28,0)) -> 1.5 | J15: =INDEX('Priority Framework'!$D$32:$D$36,MATCH(F15,'Priority Framework'!$A$32:$A$36,0)) -> 1 | K15: =IF(G15>='Priority Framework'!$C$11,G15,ROUND(G15*H15*I15*J15,2)) -> 48.75 | L15: =IF(G15>='Priority Framework'!$C$11,"YES","No") -> No | N15: =IF(M15="","n/a",IF(ABS(K15-M15)<0.005,"Ties","DIFFERS")) -> n/a | O15: =RANK(K15,$K$7:$K$15) -> 1 | P15: =RANK(Q15,$Q$7:$Q$15) -> 3 | Q15: =IF(L15="YES",1000,0)+K15 -> 48.75
A16: Edge case: a Moderate-vulnerability, VIP, Strategic, Onboarding queue scores 48.75 (13 x 2.5 x 1.5 x 1) - higher than a High-vulnerability queue at 40. Ranking by raw score alone (as the CX Rules Matrix does) would put it above the 'Mandatory Priority' queue. The 'mandatory first' rank fixes this. Confirm the intended behaviour with Daryll (Open Items #7).
A18: Part B - One agent, step by step (PROPOSED design, placeholder values - not agreed)
A19: Change the blue/purple cells to test situations. 'Things to try' at the bottom suggests some.
A20: Agent (example) | B20: Agent 1 (example)
A21: Agent's current state | B21: ='Agent Availability'!B12 -> Available (routable)
A22: Allocation check triggered? | B22: ='Agent Availability'!B13 -> YES
A23: Agent's home queue | B23: Empathy_Tel
A25: Setting | B25: Value | C25: Unit | D25: Status / source
A26: Minimum pressure for a queue to justify a move | B26: 50 | C26: points | D26: PLACEHOLDER - from the call: 'people only move if there is pressure'
A27: Minimum pressure gap: target minus home queue | B27: 15 | C27: points | D27: PLACEHOLDER - engineering draft rules file
A28: Cooldown after a move | B28: 300 | C28: seconds | D28: PLACEHOLDER - engineering draft rules file; single-event moves need rethinking
A29: Minimum agents remaining at home queue | B29: 2 | C29: agents | D29: PLACEHOLDER - 'what is the % of?' still undecided
A30: Consecutive cycles a queue must stay under pressure | B30: 2 | C30: cycles | D30: PLACEHOLDER - HLD 6.5; not yet built in the Lambda
A31: Flexible share of a dedicated team | B31: ='Priority Framework'!$D$78 -> 0.2 | C31: share | D31: Daryll's framework - ring-fencing (80% protected / 20% flexible)
A33: Live situation (illustrative - replace with live values) | B33: Value | C33: Unit
A34: Seconds since this agent last moved | B34: 900 | C34: seconds
A35: Agents from the home team already flexed out | B35: 0 | C35: agents
A36: Home team headcount today | B36: 10 | C36: agents
A37: Home team resource status | B37: Comfortable | C37: choose
A38: Home queue agents staffed | B38: 5 | C38: agents
A39: Consecutive cycles the target queue has been under pressure | B39: 3 | C39: cycles
A41: Queue | B41: Eligible for this agent? (from Agent Availability) | C41: Contacts waiting (illustrative) | D41: Pressure score (illustrative) | E41: Priority score (Part A) | F41: Mandatory priority? | G41: Passes pressure gate? | H41: Selection key | I41: Selection rank
A42: =A7 -> Empathy_Tel | B42: =IF(A42=$B$23,"Home queue",INDEX('Agent Availability'!$G$27:$G$34,MATCH(A42,'Agent Availability'!$A$27:$A$34,0))) -> Home queue | C42: 2 | D42: 30 | E42: =K7 -> 3.51 | F42: =L7 -> No | G42: =IF(B42<>"Yes","n/a",IF(AND(F42="YES",C42>=1),"PASS (mandatory)",IF(D42>=$B$26,"PASS","FAIL"))) -> n/a | H42: =IF(AND(B42="Yes",LEFT(G42,4)="PASS"),IF(F42="YES",1000,0)+E42+D42/1000,0) -> 0 | I42: =IF(H42>0,RANK(H42,$H$42:$H$49),"")
A43: =A8 -> Al_Jazeera_Tel | B43: =IF(A43=$B$23,"Home queue",INDEX('Agent Availability'!$G$27:$G$34,MATCH(A43,'Agent Availability'!$A$27:$A$34,0))) -> Yes | C43: 14 | D43: 88 | E43: =K8 -> 3.51 | F43: =L8 -> No | G43: =IF(B43<>"Yes","n/a",IF(AND(F43="YES",C43>=1),"PASS (mandatory)",IF(D43>=$B$26,"PASS","FAIL"))) -> PASS | H43: =IF(AND(B43="Yes",LEFT(G43,4)="PASS"),IF(F43="YES",1000,0)+E43+D43/1000,0) -> 3.598 | I43: =IF(H43>0,RANK(H43,$H$42:$H$49),"") -> 3
A44: =A9 -> Construction_Worker_Charitable_Trust_Tel | B44: =IF(A44=$B$23,"Home queue",INDEX('Agent Availability'!$G$27:$G$34,MATCH(A44,'Agent Availability'!$A$27:$A$34,0))) -> Yes | C44: 10 | D44: 72 | E44: =K9 -> 14.04 | F44: =L9 -> No | G44: =IF(B44<>"Yes","n/a",IF(AND(F44="YES",C44>=1),"PASS (mandatory)",IF(D44>=$B$26,"PASS","FAIL"))) -> PASS | H44: =IF(AND(B44="Yes",LEFT(G44,4)="PASS"),IF(F44="YES",1000,0)+E44+D44/1000,0) -> 14.112 | I44: =IF(H44>0,RANK(H44,$H$42:$H$49),"") -> 2
A45: =A10 -> Life_and_Progress_Assistance_Programme_Tel | B45: =IF(A45=$B$23,"Home queue",INDEX('Agent Availability'!$G$27:$G$34,MATCH(A45,'Agent Availability'!$A$27:$A$34,0))) -> Yes | C45: 6 | D45: 55 | E45: =K10 -> 17.55 | F45: =L10 -> No | G45: =IF(B45<>"Yes","n/a",IF(AND(F45="YES",C45>=1),"PASS (mandatory)",IF(D45>=$B$26,"PASS","FAIL"))) -> PASS | H45: =IF(AND(B45="Yes",LEFT(G45,4)="PASS"),IF(F45="YES",1000,0)+E45+D45/1000,0) -> 17.605 | I45: =IF(H45>0,RANK(H45,$H$42:$H$49),"") -> 1
...

Sheet Validation
A1: Validation - does this workbook reproduce the real system?
A2: Engineering-facing. Compares the workbook's formulas with (1) a real Lambda result, (2) what the demo front-end displays, and (3) Daryll's spreadsheet.
A4: 1. Real Lambda output (dry run) vs this workbook
A5: Queue | B5: Source | C5: Contacts | D5: Oldest (s) | E5: Available | F5: Staffed | G5: Lambda score | H5: Workbook score | I5: Difference | J5: Result
A6: The_Scouts_Association_Tel | B6: Real Lambda dry-run | C6: 1 | D6: 415122 | E6: 0 | F6: 0 | G6: 61.83 | H6: =ROUND(IF(C6<=0,0,(MIN(C6/'Demand Pressure'!$C$6,1)*'Demand Pressure'!$E$6+MIN(D6/'Demand Pressure'!$C$7,1)*'Demand Pressure'!$E$7+IF(F6<=0,1,MAX(0,MIN(1,1-E6/F6)))*'Demand Pressure'!$E$8+MIN(C6*'Demand Pressure'!$C$13/'Demand Pressure'!$C$9,1)*'Demand Pressure'!$E$9)/'Demand Pressure'!$E$10*'Demand Pressure'!$C$15),2) -> 61.83 | I6: =H6-G6 -> 0 | J6: =IF(ABS(I6)<=0.05,"Ties","DIFFERS") -> Ties
A7: Lambda component scores for this queue were: queue depth 0.1, oldest age 1, agent shortage 1, workload 0.3333 - the same components this workbook produces (0.1 x 0.35 + 1 x 0.35 + 1 x 0.20 + 0.3333 x 0.10 = 0.6183).
A9: 2. What the demo front-end displays ('Sample' data source) vs this workbook
A10: Queue | B10: Screen | C10: Contacts | D10: Oldest (s) | E10: Available | F10: Staffed | G10: Screen score | H10: Workbook score | I10: Difference | J10: Result
A11: Carers_UK_Tel | B11: Screen 1 | C11: 24 | D11: 492 | E11: 0 | F11: 9 | G11: 100 | H11: =ROUND(IF(C11<=0,0,(MIN(C11/'Demand Pressure'!$C$6,1)*'Demand Pressure'!$E$6+MIN(D11/'Demand Pressure'!$C$7,1)*'Demand Pressure'!$E$7+IF(F11<=0,1,MAX(0,MIN(1,1-E11/F11)))*'Demand Pressure'!$E$8+MIN(C11*'Demand Pressure'!$C$13/'Demand Pressure'!$C$9,1)*'Demand Pressure'!$E$9)/'Demand Pressure'!$E$10*'Demand Pressure'!$C$15),2) -> 100 | I11: =H11-G11 -> 0 | J11: =IF(ABS(I11)<=0.1,"Ties","DIFFERS") -> Ties
A12: Gamstop_Betting_Shops_Tel | B12: Screen 1 | C12: 26 | D12: 540 | E12: 1 | F12: 12 | G12: 98.3 | H12: =ROUND(IF(C12<=0,0,(MIN(C12/'Demand Pressure'!$C$6,1)*'Demand Pressure'!$E$6+MIN(D12/'Demand Pressure'!$C$7,1)*'Demand Pressure'!$E$7+IF(F12<=0,1,MAX(0,MIN(1,1-E12/F12)))*'Demand Pressure'!$E$8+MIN(C12*'Demand Pressure'!$C$13/'Demand Pressure'!$C$9,1)*'Demand Pressure'!$E$9)/'Demand Pressure'!$E$10*'Demand Pressure'!$C$15),2) -> 98.33 | I12: =H12-G12 -> 0.03 | J12: =IF(ABS(I12)<=0.1,"Ties","DIFFERS") -> Ties
A13: NSPCC_Tel | B13: Screen 1 | C13: 19 | D13: 392 | E13: 1 | F13: 14 | G13: 90.4 | H13: =ROUND(IF(C13<=0,0,(MIN(C13/'Demand Pressure'!$C$6,1)*'Demand Pressure'!$E$6+MIN(D13/'Demand Pressure'!$C$7,1)*'Demand Pressure'!$E$7+IF(F13<=0,1,MAX(0,MIN(1,1-E13/F13)))*'Demand Pressure'!$E$8+MIN(C13*'Demand Pressure'!$C$13/'Demand Pressure'!$C$9,1)*'Demand Pressure'!$E$9)/'Demand Pressure'!$E$10*'Demand Pressure'!$C$15),2) -> 98.57 | I13: =H13-G13 -> 8.17 | J13: =IF(ABS(I13)<=0.1,"Ties","DIFFERS") -> DIFFERS
A14: Kings_Trust_Anything_Else | B14: Screen 1 | C14: 16 | D14: 327 | E14: 1 | F14: 10 | G14: 78.3 | H14: =ROUND(IF(C14<=0,0,(MIN(C14/'Demand Pressure'!$C$6,1)*'Demand Pressure'!$E$6+MIN(D14/'Demand Pressure'!$C$7,1)*'Demand Pressure'!$E$7+IF(F14<=0,1,MAX(0,MIN(1,1-E14/F14)))*'Demand Pressure'!$E$8+MIN(C14*'Demand Pressure'!$C$13/'Demand Pressure'!$C$9,1)*'Demand Pressure'!$E$9)/'Demand Pressure'!$E$10*'Demand Pressure'!$C$15),2) -> 98 | I14: =H14-G14 -> 19.7 | J14: =IF(ABS(I14)<=0.1,"Ties","DIFFERS") -> DIFFERS
A15: Employee_Support_Hub_Plus_Tel | B15: Screen 1 | C15: 8 | D15: 164 | E15: 3 | F15: 13 | G15: 45.6 | H15: =ROUND(IF(C15<=0,0,(MIN(C15/'Demand Pressure'!$C$6,1)*'Demand Pressure'!$E$6+MIN(D15/'Demand Pressure'!$C$7,1)*'Demand Pressure'!$E$7+IF(F15<=0,1,MAX(0,MIN(1,1-E15/F15)))*'Demand Pressure'!$E$8+MIN(C15*'Demand Pressure'!$C$13/'Demand Pressure'!$C$9,1)*'Demand Pressure'!$E$9)/'Demand Pressure'!$E$10*'Demand Pressure'!$C$15),2) -> 72.52 | I15: =H15-G15 -> 26.92 | J15: =IF(ABS(I15)<=0.1,"Ties","DIFFERS") -> DIFFERS
A16: Empathy_Tel | B16: Screen 1 | C16: 6 | D16: 122 | E16: 3 | F16: 11 | G16: 37.1 | H16: =ROUND(IF(C16<=0,0,(MIN(C16/'Demand Pressure'!$C$6,1)*'Demand Pressure'!$E$6+MIN(D16/'Demand Pressure'!$C$7,1)*'Demand Pressure'!$E$7+IF(F16<=0,1,MAX(0,MIN(1,1-E16/F16)))*'Demand Pressure'!$E$8+MIN(C16*'Demand Pressure'!$C$13/'Demand Pressure'!$C$9,1)*'Demand Pressure'!$E$9)/'Demand Pressure'!$E$10*'Demand Pressure'!$C$15),2) -> 59.78 | I16: =H16-G16 -> 22.68 | J16: =IF(ABS(I16)<=0.1,"Ties","DIFFERS") -> DIFFERS
A17: BBC_Tel | B17: Screen 1 | C17: 4 | D17: 84 | E17: 3 | F17: 7 | G17: 26.7 | H17: =ROUND(IF(C17<=0,0,(MIN(C17/'Demand Pressure'!$C$6,1)*'Demand Pressure'!$E$6+MIN(D17/'Demand Pressure'!$C$7,1)*'Demand Pressure'!$E$7+IF(F17<=0,1,MAX(0,MIN(1,1-E17/F17)))*'Demand Pressure'!$E$8+MIN(C17*'Demand Pressure'!$C$13/'Demand Pressure'!$C$9,1)*'Demand Pressure'!$E$9)/'Demand Pressure'!$E$10*'Demand Pressure'!$C$15),2) -> 45.23 | I17: =H17-G17 -> 18.53 | J17: =IF(ABS(I17)<=0.1,"Ties","DIFFERS") -> DIFFERS
A18: Amica_Tel | B18: Screen 1 | C18: 3 | D18: 69 | E18: 2 | F18: 6 | G18: 25.2 | H18: =ROUND(IF(C18<=0,0,(MIN(C18/'Demand Pressure'!$C$6,1)*'Demand Pressure'!$E$6+MIN(D18/'Demand Pressure'!$C$7,1)*'Demand Pressure'!$E$7+IF(F18<=0,1,MAX(0,MIN(1,1-E18/F18)))*'Demand Pressure'!$E$8+MIN(C18*'Demand Pressure'!$C$13/'Demand Pressure'!$C$9,1)*'Demand Pressure'!$E$9)/'Demand Pressure'!$E$10*'Demand Pressure'!$C$15),2) -> 41.88 | I18: =H18-G18 -> 16.68 | J18: =IF(ABS(I18)<=0.1,"Ties","DIFFERS") -> DIFFERS
A19: Gamstop_Online_Update_Current_Exclusion_Tel | B19: Screen 1 | C19: 3 | D19: 69 | E19: 3 | F19: 8 | G19: 24.4 | H19: =ROUND(IF(C19<=0,0,(MIN(C19/'Demand Pressure'!$C$6,1)*'Demand Pressure'!$E$6+MIN(D19/'Demand Pressure'!$C$7,1)*'Demand Pressure'!$E$7+IF(F19<=0,1,MAX(0,MIN(1,1-E19/F19)))*'Demand Pressure'!$E$8+MIN(C19*'Demand Pressure'!$C$13/'Demand Pressure'!$C$9,1)*'Demand Pressure'!$E$9)/'Demand Pressure'!$E$10*'Demand Pressure'!$C$15),2) -> 41.05 | I19: =H19-G19 -> 16.65 | J19: =IF(ABS(I19)<=0.1,"Ties","DIFFERS") -> DIFFERS
A20: NSPCC_Tel | B20: Screen 2 | C20: 25 | D20: 527 | E20: 1 | F20: 14 | G20: 98.6 | H20: =ROUND(IF(C20<=0,0,(MIN(C20/'Demand Pressure'!$C$6,1)*'Demand Pressure'!$E$6+MIN(D20/'Demand Pressure'!$C$7,1)*'Demand Pressure'!$E$7+IF(F20<=0,1,MAX(0,MIN(1,1-E20/F20)))*'Demand Pressure'!$E$8+MIN(C20*'Demand Pressure'!$C$13/'Demand Pressure'!$C$9,1)*'Demand Pressure'!$E$9)/'Demand Pressure'!$E$10*'Demand Pressure'!$C$15),2) -> 98.57 | I20: =H20-G20 -> -0.03 | J20: =IF(ABS(I20)<=0.1,"Ties","DIFFERS") -> Ties
A21: Employee_Support_Hub_Plus_Tel | B21: Screen 2 | C21: 20 | D21: 408 | E21: 1 | F21: 13 | G21: 93.2 | H21: =ROUND(IF(C21<=0,0,(MIN(C21/'Demand Pressure'!$C$6,1)*'Demand Pressure'!$E$6+MIN(D21/'Demand Pressure'!$C$7,1)*'Demand Pressure'!$E$7+IF(F21<=0,1,MAX(0,MIN(1,1-E21/F21)))*'Demand Pressure'!$E$8+MIN(C21*'Demand Pressure'!$C$13/'Demand Pressure'!$C$9,1)*'Demand Pressure'!$E$9)/'Demand Pressure'!$E$10*'Demand Pressure'!$C$15),2) -> 98.46 | I21: =H21-G21 -> 5.26 | J21: =IF(ABS(I21)<=0.1,"Ties","DIFFERS") -> DIFFERS
A22: Gamstop_Betting_Shops_Tel | B22: Screen 2 | C22: 11 | D22: 219 | E22: 2 | F22: 12 | G22: 57.7 | H22: =ROUND(IF(C22<=0,0,(MIN(C22/'Demand Pressure'!$C$6,1)*'Demand Pressure'!$E$6+MIN(D22/'Demand Pressure'!$C$7,1)*'Demand Pressure'!$E$7+IF(F22<=0,1,MAX(0,MIN(1,1-E22/F22)))*'Demand Pressure'!$E$8+MIN(C22*'Demand Pressure'!$C$13/'Demand Pressure'!$C$9,1)*'Demand Pressure'!$E$9)/'Demand Pressure'!$E$10*'Demand Pressure'!$C$15),2) -> 87.22 | I22: =H22-G22 -> 29.52 | J22: =IF(ABS(I22)<=0.1,"Ties","DIFFERS") -> DIFFERS
... A25: Gamstop_Online_Update_Current_Exclusion_Tel | B25: Screen 2 | C25: 9 | D25: 183 | E25: 2 | F25: 8 | G25: 48.8 | H25: =ROUND(IF(C25<=0,0,(MIN(C25/'Demand Pressure'!$C$6,1)*'Demand Pressure'!$E$6+MIN(D25/'Demand Pressure'!$C$7,1)*'Demand Pressure'!$E$7+IF(F25<=0,1,MAX(0,MIN(1,1-E25/F25)))*'Demand Pressure'!$E$8+MIN(C25*'Demand Pressure'!$C$13/'Demand Pressure'!$C$9,1)*'Demand Pressure'!$E$9)/'Demand Pressure'!$E$10*'Demand Pressure'!$C$15),2) -> 77.85 | I25: =H25-G25 -> 29.05 | J25: =IF(ABS(I25)<=0.1,"Ties","DIFFERS") -> DIFFERS
A26: Rows that tie | C26: =COUNTIF(J11:J25,"Ties") -> 3
A27: Rows that differ | C27: =COUNTIF(J11:J25,"DIFFERS") -> 12
A28: Reading: the workbook ties on the rows where every factor is at its limit, and differs on the rest (the screen shows lower scores). That suggests the demo front-end's Sample mode uses its own thresholds or weights, or its own generator, rather than the Lambda's defaults. Check with the front-end owner before the Sample screen is presented to the business as 'the calculation'. Screen values were read from photographs, so a few digits could be misread - but the differences are large and consistent, not random.
A30: 3. Priority score vs Daryll's CX Rules Matrix
A31: Queues in this workbook that tie to the matrix | C31: =COUNTIF('Supply Calculation'!N7:N15,"Ties") -> 8 | D31: of 8
A32: Full check done during the Lambda build | C32: 48 of 48 | D32: queues
A33: The 48-queue check compared the Lambda's calculation with every Bureau and RBL queue in the matrix extract (value x weights) and found no differences. Scope: this tests the formula, not the business ratings themselves. Only Bureau/RBL rows were extracted; Mind, GamStop, King's Trust and other dedicated rows are not yet loaded.

Sheet Sources & Open Items
A1: Sources & Open Items - where every number comes from, and what is not yet decided
A2: Status key: Default = original system default, never reviewed by the business | Business rule = set by Daryll's framework | Placeholder = engineering draft, NOT agreed | Inferred = deduced from observed results
A4: 1. Sources for every hard-coded value
A5: # | B5: Item | C5: Value | D5: Where used | E5: Source | F5: Status
A6: 1 | B6: Weights: queue depth / oldest age / agent shortage / workload | C6: 0.35 / 0.35 / 0.20 / 0.10 | D6: Demand Pressure | E6: Original starting configuration file supplied at the start of the project (demand_config_example.json). Never validated with the business. | F6: Default
A7: 2 | B7: Thresholds: contacts / seconds / workload seconds | C7: 10 / 300 / 1800 | D7: Demand Pressure | E7: Same configuration file. | F7: Default
A8: 3 | B8: Default handle time | C8: 600 seconds | D8: Demand Pressure | E8: Same file. Used because handle-time data only refreshes once a day. | F8: Default
A9: 4 | B9: Maximum queue-data age | C9: 180 seconds | D9: Demand Pressure | E9: Same file. | F9: Default
A10: 5 | B10: Pressure bands | C10: 0 / 25 / 50 / 75 / 90 | D10: Demand Pressure | E10: Same file. The demo front-end labels bands differently (see Open Items #3). | F10: Default
A11: 6 | B11: Agent-shortage formula (1 - available / staffed) | C11: - | D11: Demand Pressure | E11: Deduced from real results (0 of 0 = 1; 1 of 14 = 0.929 reproduces 98.57). Not read from source. | F11: Inferred
A12: 7 | B12: Workload formula (contacts x handle time / 1800, capped) | C12: - | D12: Demand Pressure | E12: Deduced from a real result (1 x 600 / 1800 = 0.3333). Not read from source. | F12: Inferred
A13: 8 | B13: Agent states that trigger a check | C13: Available only | D13: Agent Availability | E13: HLD sections 2.1 and 6.2 (design document). | F13: Business rule
A14: 9 | B14: Vulnerability scores and Mandatory Priority threshold | C14: 50 / 40 / 13 / 10 / 0; threshold 40 | D14: Priority Framework | E14: Daryll's Framework v2 tab (transcribed from screenshots). | F14: Business rule
A15: 10 | B15: SLA, Client Value, Journey Stage levels and weights | C15: 50% / 30% / 20% | D15: Priority Framework | E15: Daryll's Framework v2 tab (transcribed from screenshots). | F15: Business rule
A16: 11 | B16: Layer 3 modifiers and waiting-time tiers | C16: various | D16: Priority Framework | E16: Daryll's Framework v2 tab. Not yet used in any calculation. | F16: Business rule
A17: 12 | B17: Ring-fencing 80% / 20%; diversion limits 20 / 15 / 10 / 5 / 0 % | C17: - | D17: Priority Framework, Supply | E17: Daryll's Framework v2 tab. | F17: Business rule
... A21: 16 | B21: Pressure, contacts and agent-profile values in Part B | C21: see sheet | D21: Supply Calculation | E21: Made up to illustrate the logic. | F21: Placeholder
A24: 2. Open items - what needs a decision or a check
A25: # | B25: Item | C25: Owner (suggested) | D25: Why it matters | E25: Where it shows in this workbook | F25: Type
A26: 1 | B26: How priority score and queue pressure combine when choosing a target queue | C26: Andrew / Daryll | D26: Two ranking signals exist and nobody has defined how they combine. Part B uses priority-first with a pressure gate, as a starting point only. | E26: Supply Calculation, Part B (see 'Things to try' #4) | F26: Decision
A27: 2 | B27: Are the pressure weights and thresholds right? | C27: Gemma / Daryll | D27: They are the original starting defaults, never reviewed against operational judgement, unlike Daryll's framework values. | E27: Demand Pressure, section 1 | F27: Decision
A28: 3 | B28: Band names and cut-offs differ between the Lambda and the front-end | C28: Andrew / front-end owner | D28: Lambda: Normal, Low, Medium, High, Critical (0/25/50/75/90). Screen: Normal, Elevated, High, Critical. Users would see different labels for the same score. | E28: Demand Pressure, bands | F28: Check
A29: 4 | B29: Verify shortage and workload formulas against the Lambda source | C29: Engineering | D29: Deduced from real results; matches every real case tested, but edge cases (e.g. staffed = 0) are inferred. | E29: Demand Pressure; Validation | F29: Check
A30: 5 | B30: Minimum staffing: what is the percentage OF, and what value? | C30: Daryll | D30: Total assigned, rostered today, or live-available give very different real numbers. | E30: Supply Calculation, setting 4 | F30: Decision
A31: 6 | B31: Placeholder guard-rail values (cooldown, pressure gap, sustained cycles) | C31: Andrew / Daryll | D31: Draft numbers only. A flat cooldown also does not suit single-event moves (e.g. one urgent call, then nothing for days). | E31: Supply Calculation, settings | F31: Decision
A32: 7 | B32: Ranking by raw score can outrank a mandatory-priority queue | C32: Daryll | D32: 13 x 2.5 x 1.5 x 1 = 48.75, which beats a High-vulnerability score of 40. The 'mandatory first' rank in this workbook avoids this - confirm that is intended. | E32: Supply Calculation, Part A edge case | F32: Decision
A33: 8 | B33: Do guard rails and the pressure gate apply to mandatory-priority moves? | C33: Daryll | D33: A single urgent call on a critical line produces low pressure and a small gap, so guard rails could block exactly the case the framework is designed to protect. | E33: Supply Calculation, 'Things to try' #1 | F33: Decision
A34: 9 | B34: Multiplicative (as in the matrix) or additive (as described on the call)? | C34: Daryll | D34: The matrix multiplies the factors. The worked example discussed on the call (85 vs 120) sounded additive. This workbook follows the matrix. | E34: Priority Framework, formula note | F34: Check
A35: 10 | B35: Layer 3 modifiers and waiting-time tiers are defined but not built | C35: Andrew | D35: They exist in the framework but no calculation uses them yet. Queue age is the natural next step as the data already exists. | E35: Priority Framework | F35: Not built
A36: 11 | B36: Reason codes and decision tiering are undefined | C36: Andrew / Daryll | D36: The decision reason is free text. Reason codes and any approval tiers need designing before decisions are logged for review. | E36: Supply Calculation, decision | F36: Decision
A37: 12 | B37: Sustained-pressure / smoothing is not built in the Lambda | C37: Engineering | D37: Each calculation is a snapshot with no memory of the previous cycle (HLD 6.5 calls for smoothing). | E37: Supply Calculation, check 7 | F37: Not built
A38: 13 | B38: Customer sentiment / repeat-caller parameter | C38: Daryll | D38: Floated as a suggestion only; would need new data capture (caller number history). Parked. | E38: Not modelled | F38: Parked
